Workbook

Sheet I-O
B1: 2022 Input-Output transactions table
B2: Industry | C2: S1 | D2: S2 | E2: S3 | F2: S4 | G2: S5 | H2: S6 | I2: S7 | J2: S8 | K2: S9 | L2: S10 | M2: S11 | N2: S12 | O2: S13 | P2: S14 | Q2: S15 | R2: S16 | S2: S17 | T2: S18 | U2: S19 | V2: S20 | W2: S21 | X2: S22 | Y2: S23 | Z2: S24 | AA2: S25 | AB2: S26 | AC2: S27 | AD2: S28 | AE2: S29 | AF2: S30 | AG2: S31 | AH2: S32 | AI2: S33 | AJ2: S34 | AK2: S35 | AL2: S36 | AM2: S37 | AN2: S38 | AO2: S39 | AP2: S40 | AQ2: S41 | AR2: S42 | AS2: S43 | AT2: S44 | AU2: S45 | AV2: S46 | AW2: S47 | AX2: S48 | AY2: S49 | AZ2: S50 | BA2: S51 | BB2: S52 | BC2: S53 | BD2: S54 | BE2: S55 | BF2: S56 | BG2: S57 | BH2: S58 | BI2: S59 | BJ2: S60 | BK2: S61 | BL2: S62 | BM2: Interindustry demand | BO2: PCE | BP2: VE | BQ2: Change in inventories | BR2: Gross private investment | BS2: State and local gov't investment | BT2: State and local gov't consumption | BU2: Federal defense consumption | BV2: Federal defense investment | BW2: Federal nondefense consumption | BX2: Federal nondefense investment | BY2: Exports | CA2: Output
A3: S1 | B3: Crop production | C3: 8.5381865 | D3: 8.3969568 | E3: 0 | F3: 0 | G3: 1.6640221 | H3: 0 | I3: 1.4474393 | J3: 2.6483887 | K3: 1.1334982 | L3: 3.8306382 | M3: 56.165439 | N3: 0 | O3: 0.34579119 | P3: 0.00031602302 | Q3: 1.3808298 | R3: 0 | S3: 0 | T3: 0 | U3: 0 | V3: 0 | W3: 0 | X3: 0 | Y3: 0 | Z3: 0 | AA3: 0 | AB3: 0 | AC3: 0 | AD3: 0 | AE3: 0 | AF3: 0 | AG3: 0.15001639 | AH3: 0.14209403 | AI3: 0 | AJ3: 0 | AK3: 0 | AL3: 2.6562587 | AM3: 0.50591263 | AN3: 0 | AO3: 0 | AP3: 0.042594292 | AQ3: 0 | AR3: 0 | AS3: 0.029811432 | AT3: 0 | AU3: 0 | AV3: 0.31940818 | AW3: 0 | AX3: 0 | AY3: 0.00020254059 | AZ3: 0 | BA3: 0.39056493 | BB3: 0.10906114 | BC3: 0.04703278 | BD3: 0.029125541 | BE3: 0 | BF3: 8.6131266 | BG3: 0.00025694845 | BH3: 0 | BI3: 0.017387604 | BJ3: 0 | BK3: 0 | BL3: 0 | BM3: =SUM(C3:BL3) -> 98.604359 | BO3: 100.24274 | BP3: 24.565133 | BQ3: 0 | BR3: 0 | BS3: 0 | BT3: 6.5844684 | BU3: 0 | BV3: 0 | BW3: 0 | BX3: 0 | BY3: 258.77357 | CA3: 488.77025
A4: S2 | B4: Animal production | C4: 0 | D4: 4.9066513 | E4: 0 | F4: 0.014359611 | G4: 6.3731374 | H4: 0 | I4: 0 | J4: 0 | K4: 0 | L4: 0 | M4: 20.401501 | N4: 0 | O4: 0 | P4: 0 | Q4: 0.00059786306 | R4: 0 | S4: 0 | T4: 0 | U4: 0 | V4: 0 | W4: 0 | X4: 0 | Y4: 0 | Z4: 0 | AA4: 0 | AB4: 0 | AC4: 0 | AD4: 0 | AE4: 0 | AF4: 0 | AG4: 0.040582459 | AH4: 0.030475902 | AI4: 0 | AJ4: 0 | AK4: 0 | AL4: 0 | AM4: 0 | AN4: 0 | AO4: 0 | AP4: 0 | AQ4: 0 | AR4: 2.2652355 | AS4: 0 | AT4: 0 | AU4: 0 | AV4: 0.0022269757 | AW4: 0 | AX4: 0.0065253905 | AY4: 0 | AZ4: 0 | BA4: 3.2901857 | BB4: 0.039085363 | BC4: 0.00081745056 | BD4: 0.15555654 | BE4: 0 | BF4: 10.856264 | BG4: 0 | BH4: 1.3991243 | BI4: 0.00015722824 | BJ4: 0 | BK4: 0 | BL4: 0 | BM4: =SUM(C4:BL4) -> 49.782483 | BO4: 32.443013 | BP4: 1.6741951 | BQ4: 0 | BR4: 0 | BS4: 0 | BT4: 0.61605677 | BU4: 0 | BV4: 0 | BW4: 0 | BX4: 0 | BY4: 74.766259 | CA4: 159.282
A5: S3 | B5: Commercial fishing | C5: 0 | D5: 0 | E5: 1.0241778 | F5: 0 | G5: 0 | H5: 0 | I5: 0 | J5: 0 | K5: 0 | L5: 0 | M5: 0.41638406 | N5: 0 | O5: 0 | P5: 0 | Q5: 0 | R5: 0 | S5: 0 | T5: 0 | U5: 0 | V5: 0 | W5: 0 | X5: 0 | Y5: 0 | Z5: 0 | AA5: 0 | AB5: 0 | AC5: 0 | AD5: 0 | AE5: 0 | AF5: 0 | AG5: 0 | AH5: 0 | AI5: 0 | AJ5: 0 | AK5: 0 | AL5: 0 | AM5: 0 | AN5: 0 | AO5: 0 | AP5: 0 | AQ5: 0 | AR5: 0 | AS5: 0 | AT5: 0 | AU5: 0 | AV5: 0 | AW5: 0 | AX5: 0 | AY5: 0 | AZ5: 0 | BA5: 2.0892656 | BB5: 0.082190336 | BC5: 0 | BD5: 0.0022121324 | BE5: 0 | BF5: 50.564143 | BG5: 0 | BH5: 0 | BI5: 0.014061734 | BJ5: 0 | BK5: 0 | BL5: 0 | BM5: =SUM(C5:BL5) -> 54.192435 | BO5: 24.305093 | BP5: 2.0611506 | BQ5: 0 | BR5: 0 | BS5: 0 | BT5: 0.83359265 | BU5: 0 | BV5: 0 | BW5: 0 | BX5: 0 | BY5: 87.71279 | CA5: 169.10505
A6: S4 | B6: Forestry & logging | C6: 1.0119086 | D6: 0 | E6: 0 | F6: 4.6571413 | G6: 2.6339373 | H6: 2.995254 | I6: 0 | J6: 0 | K6: 0 | L6: 0 | M6: 0.16988413 | N6: 0.66966574 | O6: 0.3685589 | P6: 0.20016018 | Q6: 0.32921154 | R6: 0 | S6: 0.021167589 | T6: 0 | U6: 0 | V6: 0 | W6: 0 | X6: 0 | Y6: 0 | Z6: 0 | AA6: 0 | AB6: 0 | AC6: 0 | AD6: 0 | AE6: 0 | AF6: 0 | AG6: 0 | AH6: 0 | AI6: 0 | AJ6: 0 | AK6: 0 | AL6: 0 | AM6: 0 | AN6: 0 | AO6: 0 | AP6: 0 | AQ6: 0 | AR6: 1.1349575 | AS6: 0 | AT6: 0 | AU6: 0 | AV6: 0.41064789 | AW6: 0 | AX6: 0.0252469 | AY6: 0 | AZ6: 0 | BA6: 0 | BB6: 0 | BC6: 0 | BD6: 0.011975948 | BE6: 0 | BF6: 0 | BG6: 0.0028171382 | BH6: 0 | BI6: 0 | BJ6: 0 | BK6: 0 | BL6: 0 | BM6: =SUM(C6:BL6) -> 14.642535 | BO6: 0 | BP6: 0 | BQ6: 0 | BR6: 0 | BS6: 0 | BT6: 0 | BU6: 0 | BV6: 0 | BW6: 0 | BX6: 0 | BY6: 0 | CA6: 14.64253
A7: S5 | B7: Support activities for agriculture | C7: 29.192728 | D7: 0.58153411 | E7: 0 | F7: 0.11517377 | G7: 2.3004131 | H7: 0 | I7: 0 | J7: 0 | K7: 0 | L7: 0 | M7: 0 | N7: 0 | O7: 0 | P7: 0 | Q7: 0.60145955 | R7: 0.032094051 | S7: 0.00086566914 | T7: 0 | U7: 0 | V7: 0.048206724 | W7: 0 | X7: 0 | Y7: 0.00090775831 | Z7: 0 | AA7: 0.00019143739 | AB7: 0.0059559674 | AC7: 5.074651e-05 | AD7: 1.6653421e-05 | AE7: 0.029184629 | AF7: 0.0045300687 | AG7: 0 | AH7: 0 | AI7: 0.0011107979 | AJ7: 0 | AK7: 0 | AL7: 29.878822 | AM7: 3.3770791 | AN7: 0 | AO7: 0.0010076152 | AP7: 0 | AQ7: 0.00021757235 | AR7: 0 | AS7: 0 | AT7: 0.00019548458 | AU7: 0 | AV7: 0 | AW7: 0 | AX7: 0 | AY7: 0 | AZ7: 0.00062337292 | BA7: 0 | BB7: 0 | BC7: 0 | BD7: 0 | BE7: 0.18409218 | BF7: 0 | BG7: 0 | BH7: 0 | BI7: 0 | BJ7: 0 | BK7: 0.070744955 | BL7: 0.18772866 | BM7: =SUM(C7:BL7) -> 66.614933 | BO7: 108.76256 | BP7: 0 | BQ7: 0 | BR7: 0 | BS7: 0 | BT7: 0 | BU7: 0 | BV7: 0 | BW7: 0 | BX7: 0 | BY7: 0 | CA7: 175.37747
A8: S6 | B8: Mining | C8: 0.13628429 | D8: 0 | E8: 0 | F8: 2.8548435e-05 | G8: 0.00059135841 | H8: 0.91683476 | I8: 0 | J8: 0 | K8: 0 | L8: 0 | M8: 0 | N8: 0 | O8: 0 | P8: 0 | Q8: 0 | R8: 0 | S8: 0 | T8: 0 | U8: 0 | V8: 0 | W8: 0 | X8: 0 | Y8: 0 | Z8: 0 | AA8: 0 | AB8: 0 | AC8: 0 | AD8: 0 | AE8: 2.3811771 | AF8: 4.3033001 | AG8: 0 | AH8: 0 | AI8: 0 | AJ8: 0 | AK8: 0 | AL8: 0 | AM8: 0 | AN8: 0 | AO8: 0 | AP8: 0 | AQ8: 0 | AR8: 0 | AS8: 0 | AT8: 0 | AU8: 0 | AV8: 0 | AW8: 0 | AX8: 0 | AY8: 0 | AZ8: 0 | BA8: 0 | BB8: 0 | BC8: 0 | BD8: 0 | BE8: 0 | BF8: 0 | BG8: 0 | BH8: 0 | BI8: 0 | BJ8: 0 | BK8: 0 | BL8: 0 | BM8: =SUM(C8:BL8) -> 7.7382162 | BO8: 0 | BP8: 0 | BQ8: 0 | BR8: 0 | BS8: 0 | BT8: 0 | BU8: 0 | BV8: 0 | BW8: 0.18648008 | BX8: 0 | BY8: 146.24597 | CA8: 154.17066
A9: S7 | B9: Single family construction | C9: 0 | D9: 0 | E9: 0 | F9: 0 | G9: 0 | H9: 0 | I9: 0 | J9: 0 | K9: 0 | L9: 0 | M9: 0 | N9: 0 | O9: 0 | P9: 0 | Q9: 0 | R9: 0 | S9: 0 | T9: 0 | U9: 0 | V9: 0 | W9: 0 | X9: 0 | Y9: 0 | Z9: 0 | AA9: 0 | AB9: 0 | AC9: 0 | AD9: 0 | AE9: 0 | AF9: 0 | AG9: 0 | AH9: 0 | AI9: 0 | AJ9: 0 | AK9: 0 | AL9: 0 | AM9: 0 | AN9: 0 | AO9: 0 | AP9: 0 | AQ9: 0 | AR9: 0 | AS9: 0 | AT9: 0 | AU9: 0 | AV9: 0 | AW9: 0 | AX9: 0 | AY9: 0 | AZ9: 0 | BA9: 0 | BB9: 0 | BC9: 0 | BD9: 0 | BE9: 0 | BF9: 0 | BG9: 0 | BH9: 0 | BI9: 0 | BJ9: 0 | BK9: 0 | BL9: 0 | BM9: =SUM(C9:BL9) -> 0 | BO9: 0 | BP9: 0 | BQ9: 0 | BR9: 1161.9896 | BS9: 0 | BT9: 0 | BU9: 0 | BV9: 0 | BW9: 0 | BX9: 0 | BY9: 0 | CA9: 1161.9896
A10: S8 | B10: Construction of other buildings | C10: 0 | D10: 0 | E10: 0 | F10: 0 | G10: 0 | H10: 0 | I10: 0 | J10: 0 | K10: 0 | L10: 0 | M10: 0 | N10: 0 | O10: 0 | P10: 0 | Q10: 0 | R10: 0 | S10: 0 | T10: 0 | U10: 0 | V10: 0 | W10: 0 | X10: 0 | Y10: 0 | Z10: 0 | AA10: 0 | AB10: 0 | AC10: 0 | AD10: 0 | AE10: 0 | AF10: 0 | AG10: 0 | AH10: 0 | AI10: 0 | AJ10: 0 | AK10: 0 | AL10: 0 | AM10: 0 | AN10: 0 | AO10: 0 | AP10: 0 | AQ10: 0 | AR10: 0 | AS10: 0 | AT10: 0 | AU10: 0 | AV10: 0 | AW10: 0 | AX10: 0 | AY10: 0 | AZ10: 0 | BA10: 0 | BB10: 0 | BC10: 0 | BD10: 0 | BE10: 0 | BF10: 0 | BG10: 0 | BH10: 0 | BI10: 0 | BJ10: 0 | BK10: 0 | BL10: 0 | BM10: =SUM(C10:BL10) -> 0 | BO10: 0 | BP10: 0 | BQ10: 0 | BR10: 3769.4173 | BS10: 924.24328 | BT10: 0 | BU10: 0 | BV10: 95.49252 | BW10: 0 | BX10: 47.172703 | BY10: 0 | CA10: 4836.3258
A11: S9 | B11: Heavy and civil engineering construction | C11: 0 | D11: 0 | E11: 0 | F11: 0 | G11: 0 | H11: 0 | I11: 0 | J11: 0 | K11: 0 | L11: 0 | M11: 0 | N11: 0 | O11: 0 | P11: 0 | Q11: 0 | R11: 0 | S11: 0 | T11: 0 | U11: 0 | V11: 0 | W11: 0 | X11: 0 | Y11: 0 | Z11: 0 | AA11: 0 | AB11: 0 | AC11: 0 | AD11: 0 | AE11: 0 | AF11: 0 | AG11: 0 | AH11: 0 | AI11: 0 | AJ11: 0 | AK11: 0 | AL11: 0 | AM11: 0 | AN11: 0 | AO11: 0 | AP11: 0 | AQ11: 0 | AR11: 0 | AS11: 0 | AT11: 0 | AU11: 0 | AV11: 0 | AW11: 0 | AX11: 0 | AY11: 0 | AZ11: 0 | BA11: 0 | BB11: 0 | BC11: 0 | BD11: 0 | BE11: 0 | BF11: 0 | BG11: 0 | BH11: 0 | BI11: 0 | BJ11: 0 | BK11: 0 | BL11: 0 | BM11: =SUM(C11:BL11) -> 0 | BO11: 0 | BP11: 0 | BQ11: 0 | BR11: 1359.1321 | BS11: 1399.3439 | BT11: 0 | BU11: 0 | BV11: 18.381739 | BW11: 0 | BX11: 11.687236 | BY11: 0 | CA11: 2788.545
A12: S10 | B12: Maintenance & repairs | C12: 1.6458905 | D12: 0.25997292 | E12: 20.476315 | F12: 0.0017674563 | G12: 0.31308327 | H12: 0.0056098928 | I12: 1.3586608 | J12: 9.3920204 | K12: 7.2095943 | L12: 4.937027 | M12: 7.8507114 | N12: 0.69737629 | O12: 0.17525611 | P12: 1.4681342 | Q12: 1.3580373 | R12: 132.07305 | S12: 0.025495998 | T12: 0.20821224 | U12: 0 | V12: 5.975214 | W12: 1.7455474 | X12: 1.7345743 | Y12: 3.1863516 | Z12: 2.7990962 | AA12: 0.55918497 | AB12: 17.397268 | AC12: 0.2622134 | AD12: 0.086050256 | AE12: 161.22645 | AF12: 26.708392 | AG12: 13.707423 | AH12: 43.668212 | AI12: 40.987437 | AJ12: 0.54939195 | AK12: 3.8136635 | AL12: 1037.6781 | AM12: 124.41123 | AN12: 6.4138198 | AO12: 5.3643505 | AP12: 7.6599744 | AQ12: 0.30929371 | AR12: 20.813718 | AS12: 7.1636058 | AT12: 17.318506 | AU12: 1.4107857 | AV12: 1.7332617 | AW12: 1.0823461 | AX12: 0.41650025 | AY12: 10.873885 | AZ12: 2.0596027 | BA12: 29.600313 | BB12: 4.5937816 | BC12: 3.6338538 | BD12: 1.9167031 | BE12: 490.13385 | BF12: 179.89718 | BG12: 0.90935159 | BH12: 13.831323 | BI12: 2.972767 | BJ12: 0 | BK12: 32.971791 | BL12: 13.549606 | BM12: =SUM(C12:BL12) -> 2532.5822 | BO12: 410.53387 | BP12: 0 | BQ12: 0 | BR12: 0 | BS12: 0 | BT12: 0 | BU12: 30.88315 | BV12: 112.2929 | BW12: 0 | BX12: 0 | BY12: 280.8482 | CA12: 3367.1395
A13: S11 | B13: Food processing | C13: 0.20061159 | D13: 4.0105684 | E13: 0.0094439814 | F13: 0.009916852 | G13: 0.14033734 | H13: 0 | I13: 0 | J13: 0 | K13: 0 | L13: 0 | M13: 27.438855 | N13: 24.359072 | O13: 0.13789508 | P13: 0.19020718 | Q13: 0.14502651 | R13: 0 | S13: 0.031378653 | T13: 0 | U13: 0 | V13: 2.5763147 | W13: 0.42102834 | X13: 0 | Y13: 0.054111715 | Z13: 1.008624 | AA13: 0 | AB13: 0 | AC13: 0 | AD13: 0 | AE13: 0 | AF13: 0 | AG13: 0.82190002 | AH13: 0.50738059 | AI13: 0 | AJ13: 0 | AK13: 0 | AL13: 0 | AM13: 0 | AN13: 0 | AO13: 0 | AP13: 0 | AQ13: 0 | AR13: 0.42014004 | AS13: 1.2100074 | AT13: 0 | AU13: 0 | AV13: 0.0029201458 | AW13: 0 | AX13: 0.0090701247 | AY13: 0.0017476863 | AZ13: 0.0040349882 | BA13: 13.145095 | BB13: 6.72647 | BC13: 2.8968509 | BD13: 0.071392393 | BE13: 5.305507 | BF13: 259.58437 | BG13: 0 | BH13: 0.42171541 | BI13: 0.28088153 | BJ13: 0 | BK13: 1.3925484 | BL13: 0.075079326 | BM13: =SUM(C13:BL13) -> 353.6105 | BO13: 275.96967 | BP13: 36.758369 | BQ13: 0.53506616 | BR13: 0 | BS13: 0 | BT13: 15.711225 | BU13: 4.4242067 | BV13: 0 | BW13: 0.39464466 | BX13: 0 | BY13: 342.50937 | CA13: 1029.913
A14: S12 | B14: Beverage manufacturing | C14: 0 | D14: 0.011609399 | E14: 0.96093889 | F14: 0 | G14: 0 | H14: 0 | I14: 0 | J14: 0 | K14: 0 | L14: 0 | M14: 5.7202159 | N14: 12.093982 | O14: 0.019930818 | P14: 0.027491804 | Q14: 0.016769253 | R14: 0 | S14: 0.0036282785 | T14: 0 | U14: 0 | V14: 0.29789639 | W14: 0.049011392 | X14: 0 | Y14: 0.0062568771 | Z14: 0.11662606 | AA14: 0 | AB14: 0 | AC14: 0 | AD14: 0 | AE14: 0 | AF14: 0 | AG14: 0.095035381 | AH14: 0.058667851 | AI14: 0 | AJ14: 0 | AK14: 0 | AL14: 0 | AM14: 0 | AN14: 0 | AO14: 0 | AP14: 0 | AQ14: 0 | AR14: 0 | AS14: 0.067262487 | AT14: 0 | AU14: 0 | AV14: 0 | AW14: 0 | AX14: 0.0032601714 | AY14: 0.0042820577 | AZ14: 0.00046656117 | BA14: 0.75285949 | BB14: 0.081571709 | BC14: 0.33495963 | BD14: 0.0082550227 | BE14: 0.61346985 | BF14: 83.518187 | BG14: 0 | BH14: 0 | BI14: 0.29224733 | BJ14: 0 | BK14: 0.61604234 | BL14: 0.21671331 | BM14: =SUM(C14:BL14) -> 105.98764 | BO14: 311.82324 | BP14: 15.278001 | BQ14: 0.3808399 | BR14: 0 | BS14: 0 | BT14: 18.407665 | BU14: 0.0027006642 | BV14: 0 | BW14: 0.11537332 | BX14: 0 | BY14: 14.68086 | CA14: 466.67629
... A64: S62 | B64: State and local government | C64: 5.2813698 | D64: 2.6950364 | E64: 0.19810529 | F64: 0 | G64: 0 | H64: 0.025964244 | I64: 0 | J64: 0 | K64: 0 | L64: 0 | M64: 1.5168324 | N64: 7.2384493 | O64: 0.16191807 | P64: 12.984786 | Q64: 4.9521033 | R64: 505.03101 | S64: 12.148015 | T64: 1.6573962 | U64: 11.720029 | V64: 4.2841661 | W64: 36.411267 | X64: 0.69898082 | Y64: 2.6603921 | Z64: 1.1085737 | AA64: 0.55170347 | AB64: 8.5113365 | AC64: 0.051693202 | AD64: 0.016966192 | AE64: 3.8060106 | AF64: 0.10067376 | AG64: 6.9944225 | AH64: 130.86008 | AI64: 12.130406 | AJ64: 4.2499319 | AK64: 0.99456828 | AL64: 0 | AM64: 79.830966 | AN64: 171.14741 | AO64: 3.5631358 | AP64: 0 | AQ64: 0.10020231 | AR64: 3.5639323 | AS64: 6.8362135 | AT64: 7.238115 | AU64: 1.6688254 | AV64: 5.7020106 | AW64: 62.501671 | AX64: 0.34876376 | AY64: 0.40087994 | AZ64: 0.90243144 | BA64: 73.377864 | BB64: 0 | BC64: 1.1274602 | BD64: 3.472552 | BE64: 180.49929 | BF64: 43.882155 | BG64: 0 | BH64: 2.1179885 | BI64: 0 | BJ64: 0 | BK64: 9.40542 | BL64: 5.0514291 | BM64: =SUM(C64:BL64) -> 1441.7809 | BO64: 5163.1967 | BP64: 100.04999 | BQ64: 0 | BR64: 0 | BS64: 0 | BT64: 2410.852 | BU64: 0.11283455 | BV64: 0 | BW64: 21.160655 | BX64: 0 | BY64: 0 | CA64: 9137.1528
BM65: =+SUM(BM3:BM64) -> 40963.58
B66: Intermediate demand | C66: =SUM(C3:C64) -> 130.26612 | D66: =SUM(D3:D64) -> 37.83655 | E66: =SUM(E3:E64) -> 51.679875 | F66: =SUM(F3:F64) -> 5.0579977 | G66: =SUM(G3:G64) -> 55.40831 | H66: =SUM(H3:H64) -> 54.905408 | I66: =SUM(I3:I64) -> 397.38246 | J66: =SUM(J3:J64) -> 1759.5121 | ... BL66: =SUM(BL3:BL64) -> 136.34871 | BM66: =SUM(C66:BL66) -> 40963.58 | BO66: =+SUM(BO3:BO64) -> 62731.926 | BP66: =+SUM(BP3:BP64) -> 21195.175 | BQ66: =+SUM(BQ3:BQ64) -> 23.833183 | BR66: =+SUM(BR3:BR64) -> 8567.705 | BS66: =+SUM(BS3:BS64) -> 2482.7292 | BT66: =+SUM(BT3:BT64) -> 4406.8903 | BU66: =+SUM(BU3:BU64) -> 8716.7647 | BV66: =+SUM(BV3:BV64) -> 295.36304 | ... BY66: =+SUM(BY3:BY64) -> 7258.2872 | CA66: =+SUM(CA3:CA64) -> 158618.07
B67: Imports | C67: 77.207241 | D67: 29.775526 | E67: 20.332291 | F67: 1.1774179 | G67: 19.035977 | H67: 8.7652549 | I67: 211.35708 | J67: 774.12731 | K67: 446.73359 | L67: 609.39192 | M67: 201.35918 | N67: 96.976045 | O67: 14.31403 | P67: 2287.25 | Q67: 152.68339 | R67: 528.60243 | S67: 17.203128 | T67: 7.904875 | U67: 50.000115 | V67: 158.43093 | W67: 32.797126 | X67: 9.4113704 | Y67: 208.8226 | Z67: 62.567432 | AA67: 44.810197 | AB67: 872.82742 | AC67: 15.830676 | AD67: 5.8378505 | AE67: 137.7255 | AF67: 114.78842 | AG67: 512.22218 | AH67: 796.8142 | AI67: 531.94718 | AJ67: 130.32824 | AK67: 193.15673 | AL67: 320.35035 | AM67: 154.17052 | AN67: 177.81851 | AO67: 82.803835 | AP67: 132.28674 | AQ67: 13.556494 | AR67: 290.15656 | AS67: 208.93494 | AT67: 73.139687 | AU67: 35.341669 | AV67: 60.164299 | AW67: 32.720539 | AX67: 3.5477907 | AY67: 8.5359838 | AZ67: 163.16678 | BA67: 844.30618 | BB67: 85.300012 | BC67: 30.458452 | BD67: 16.450099 | BE67: 882.31512 | BF67: 1188.4896 | BG67: 57.937492 | BH67: 102.28341 | BI67: 25.79092 | BJ67: 0 | BK67: 82.357409 | BL67: 46.394346 | BM67: =+SUM(C67:BL67) -> 14501.293 | BO67: 10288.719 | BP67: 1450.1507 | BQ67: 22.502766 | BR67: 8477.4453 | BS67: 228.57951 | BT67: 6798.93 | BU67: 274.55027 | BV67: 97.055048 | BW67: 148.80802 | BX67: 98.191865 | BY67: 964.74182 | CA67: =+SUM(BO67:BZ67)+BM67 -> 43350.967
B69: Compensation of employees | C69: 122.98711 | D69: 40.079429 | E69: 71.180589 | F69: 6.1634107 | G69: 44.129462 | H69: 33.06 | I69: 362.84871 | J69: 1510.2154 | K69: 870.76505 | L69: 1051.4399 | M69: 311.881 | N69: 98.637 | O69: 25.064 | P69: 85.217369 | Q69: 362.00663 | R69: 1130.266 | S69: 173.688 | T69: 250.557 | U69: 195.118 | V69: 668.646 | W69: 139.82682 | X69: 53.228178 | Y69: 206.95391 | Z69: 176.475 | AA69: 103.32973 | AB69: 363.683 | AC69: 44.308892 | AD69: 15.318464 | AE69: 508.29396 | AF69: 116.68004 | AG69: 1521.088 | AH69: 3199.156 | AI69: 820.866 | AJ69: 797.688 | AK69: 234.933 | AL69: 0 | AM69: 713.03285 | AN69: 299.67315 | AO69: 627.8126 | AP69: 537.11353 | AQ69: 324.28971 | AR69: 548.36835 | AS69: 874.95181 | AT69: 1182.23 | AU69: 511.51011 | AV69: 1381.6969 | AW69: 182.621 | AX69: 301.59053 | AY69: 117.78691 | AZ69: 1924.71 | BA69: 1793.984 | BB69: 463.292 | BC69: 334.2775 | BD69: 643.144 | BE69: 2895.626 | BF69: 2629.691 | BG69: 366.40163 | BH69: 454.47607 | BI69: 80.738687 | BJ69: 7012.7115 | BK69: 2340.7526 | BL69: 7682.026 | BM69: =+SUM(C69:BL69) -> 51940.287
B70: Proprietor's income | C70: 47.692259 | D70: 15.542105 | E70: 8.5874286 | F70: 0.74357139 | G70: 17.112637 | H70: 3.726 | I70: 78.337547 | J70: 326.0493 | K70: 187.9946 | L70: 227.00155 | M70: -1.281 | N70: 0.251 | O70: 5.481 | P70: 0.70458088 | Q70: 92.994581 | R70: 11.11 | S70: -2.463 | T70: 54.561 | U70: 143.704 | V70: 85.267 | W70: 1.7455266 | X70: 0.66447338 | Y70: -4.7124114 | Z70: 15.445 | AA70: -2.3528534 | AB70: -7.022 | AC70: -1.0089286 | AD70: -0.34880666 | AE70: 11.840895 | AF70: 2.7181047 | AG70: 68.26 | AH70: 173.038 | AI70: 14.755 | AJ70: 29.826 | AK70: 11.378 | AL70: 0 | AM70: 1328.4391 | AN70: 558.31586 | AO70: 197.93539 | AP70: 169.33998 | AQ70: 102.24135 | AR70: 172.88838 | AS70: 275.8529 | AT70: 1.656 | AU70: 99.031363 | AV70: 267.50464 | AW70: 12.92 | AX70: 22.132967 | AY70: 36.923033 | AZ70: 469.217 | BA70: 1.417 | BB70: 87.548 | BC70: 45.924 | BD70: 260.246 | BE70: 127.091 | BF70: 253.172 | BG70: 122.7665 | BH70: 276.54667 | BI70: 98.258266 | BJ70: 0 | BK70: 0 | BL70: 0 | BM70: =+SUM(C70:BL70) -> 6604.7096
B71: Taxes on Production and Imports less Subsidies | C71: -3.3549062 | D71: -1.0933075 | E71: 2.6735055 | F71: 0.23149447 | G71: -1.2037864 | H71: 6.078 | I71: 12.570693 | J71: 52.320578 | K71: 30.167175 | L71: 36.426554 | M71: 28.675499 | N71: 12.993501 | O71: 1.07 | P71: 7.1510639 | Q71: 29.381936 | R71: 983.749 | S71: 21.797 | T71: 57.481 | U71: 7.727 | V71: 12.484546 | W71: 1.9774543 | X71: 0.61 | Y71: 4.037 | Z71: 8.665 | AA71: 9.7290049 | AB71: 78.503995 | AC71: 2.4291832 | AD71: 0.83981685 | AE71: 326.01785 | AF71: 74.838146 | AG71: 773.513 | AH71: 2836.754 | AI71: 71.731618 | AJ71: 231.938 | AK71: 13.839382 | AL71: 0 | AM71: 1544.2319 | AN71: 649.00913 | AO71: 83.965 | AP71: 28.582639 | AQ71: 76.356 | AR71: 29.181568 | AS71: 46.560793 | AT71: 15.603 | AU71: 32.141099 | AV71: 86.819901 | AW71: 27.285 | AX71: 47.696734 | AY71: 16.765266 | AZ71: 109.116 | BA71: 50.452 | BB71: 18.476 | BC71: 55.062 | BD71: 123.13 | BE71: 1371.686 | BF71: 200.227 | BG71: 39.605529 | BH71: 49.894889 | BI71: 10 | BJ71: -1.158 | BK71: 0 | BL71: -269.44 | BM71: =+SUM(C71:BL71) -> 10173.999
B72: Other capital costs | C72: 113.97243 | D72: 37.141697 | E72: 14.651363 | F72: 1.2686375 | G72: 40.894872 | H72: 47.636 | I72: 99.493139 | J72: 414.10115 | K72: 238.76383 | L72: 288.30488 | M72: 54.841429 | N72: 66.701571 | O72: 3.185 | P72: 398.32699 | Q72: 212.21685 | R72: 865.375 | S72: 167.978 | T72: 92.801 | U72: 39.551 | V72: 293.00188 | W72: 24.250776 | X72: 5.6973489 | Y72: 51.4215 | Z72: 231.815 | AA72: 205.88824 | AB72: 828.24738 | AC72: 90.029792 | AD72: 31.125086 | AE72: 1071.7757 | AF72: 263.4353 | AG72: 976.339 | AH72: 1618.352 | AI72: 1067.2474 | AJ72: 929.848 | AK72: -47.150382 | AL72: 9603.419 | AM72: 2372.335 | AN72: 997.04398 | AO72: 1.8870091 | AP72: 44.866468 | AQ72: 374.71294 | AR72: 45.806613 | AS72: 73.086966 | AT72: 109.011 | AU72: 76.808272 | AV72: 236.98773 | AW72: 120.774 | AX72: 493.71008 | AY72: 66.694475 | AZ72: 1608.357 | BA72: 265.847 | BB72: -34.116 | BC72: 339.5365 | BD72: 270.68 | BE72: 1863.197 | BF72: 562.11 | BG72: 272.49954 | BH72: 1.0670379 | BI72: 737.14518 | BJ72: 1162.6824 | BK72: 387.70184 | BL72: 1541.8238 | BM72: =+SUM(C72:BL72) -> 34434.204
B73: Value added | C73: 281.29689 | D73: 91.669924 | E73: 97.092886 | F73: 8.407114 | G73: 100.93318 | H73: 90.5 | I73: 553.25009 | J73: 2302.6864 | K73: 1327.6907 | L73: 1603.1729 | M73: 394.11693 | N73: 178.58307 | O73: 34.8 | P73: 491.4 | Q73: 696.6 | R73: 2990.5 | S73: 361 | T73: 455.4 | U73: 386.1 | V73: 1059.3994 | W73: 167.80058 | X73: 60.2 | Y73: 257.7 | Z73: 432.4 | AA73: 316.59412 | AB73: 1263.4124 | AC73: 135.75894 | AD73: 46.93456 | AE73: 1917.9284 | AF73: 457.6716 | AG73: 3339.2 | AH73: 7827.3 | AI73: 1974.6 | AJ73: 1989.3 | AK73: 213 | AL73: 9603.419 | AM73: 5958.0389 | AN73: 2504.0421 | AO73: 911.6 | AP73: 779.90261 | AQ73: 877.6 | AR73: 796.24491 | AS73: 1270.4525 | AT73: 1308.5 | AU73: 719.49084 | AV73: 1973.0092 | AW73: 343.6 | AX73: 865.13032 | AY73: 238.16968 | AZ73: 4111.4 | BA73: 2111.7 | BB73: 535.2 | BC73: 774.8 | BD73: 1297.2 | BE73: 6257.6 | BF73: 3645.2 | BG73: 801.2732 | BH73: 781.98467 | BI73: 926.14214 | BJ73: 8174.2358 | BK73: 2728.4544 | BL73: 8954.4098 | BM73: =+SUM(C73:BL73) -> 103153.2
B75: Output | C75: 488.77025 | D75: 159.282 | E75: 169.10505 | F75: 14.64253 | G75: 175.37747 | H75: 154.17066 | I75: 1161.9896 | J75: 4836.3258 | K75: 2788.545 | L75: 3367.1395 | M75: 1029.913 | N75: 466.67629 | O75: 70.365944 | P75: 2991.6094 | Q75: 983.60706 | R75: 4942.578 | S75: 417.61 | T75: 516.724 | U75: 572.27244 | V75: 2130.1676 | W75: 337.40188 | X75: 128.4395 | Y75: 831.58693 | Z75: 722.42225 | AA75: 415.20189 | AB75: 3350.292 | AC75: 178.043 | AD75: 61.553 | AE75: 3541.4 | AF75: 812.93649 | AG75: 4926.8152 | AH75: 10832.069 | AI75: 4714.5037 | AJ75: 2858.2201 | AK75: 909.58244 | AL75: 12888.098 | AM75: 7995.88 | AN75: 3360.5052 | AO75: 1839.8455 | AP75: 1574.046 | AQ75: 950.352 | AR75: 1607.029 | AS75: 2564.103 | AT75: 1839.3234 | AU75: 899.36355 | AV75: 2429.371 | AW75: 637.561 | AX75: 901.92273 | AY75: 317.02328 | AZ75: 4927.027 | BA75: 5451.497 | BB75: 826.843 | BC75: 912.508 | BD75: 1385.704 | BE75: 12175.872 | BF75: 7531.7134 | BG75: 937.49539 | BH75: 1181.053 | BI75: 1083.5929 | BJ75: 8174.2358 | BK75: 3031.616 | BL75: 9137.1528 | BM75: 143110.57 | BO75: =+BO66+BO67 -> 73020.645 | BP75: =+BP66+BP67 -> 22645.325 | BQ75: =+BQ66+BQ67 -> 46.33595 | BR75: =+BR66+BR67 -> 17045.15 | BS75: =+BS66+BS67 -> 2711.3087 | BT75: =+BT66+BT67 -> 11205.82 | BU75: =+BU66+BU67 -> 8991.315 | BV75: =+BV66+BV67 -> 392.41808 | ... BY75: =+BY66+BY67 -> 8223.029 | CA75: =+CA66+CA67 -> 201969.04
B77: Wage and salary jobs | C77: 3387.553 | D77: 1103.9465 | E77: 1495.5065 | F77: 129.49346 | G77: 1215.5005 | H77: 256 | I77: 3606.8143 | J77: 15011.949 | K77: 8655.64 | L77: 10451.597 | M77: 5862 | N77: 1261 | O77: 489 | P77: 389.32644 | Q77: 4527.6736 | R77: 9385 | S77: 1230 | T77: 3329 | U77: 3944 | V77: 8616 | W77: 2229.3489 | X77: 848.65106 | Y77: 1291.946 | Z77: 2423 | AA77: 645.05396 | AB77: 3227 | AC77: 617 | AD77: 306 | AE77: 2940.9079 | AF77: 675.09215 | AG77: 17333 | AH77: 64327 | AI77: 7718 | AJ77: 7403 | AK77: 1223 | AL77: 0 | AM77: 8791.9309 | AN77: 3695.0691 | AO77: 5648.4114 | AP77: 4832.3945 | AQ77: 2917.6249 | AR77: 4933.6538 | AS77: 7871.9155 | AT77: 8670 | AU77: 9441.5036 | AV77: 25503.496 | AW77: 2136 | AX77: 3747.6261 | AY77: 12387.374 | AZ77: 32521 | BA77: 16395 | BB77: 7893 | BC77: 16530 | BD77: 12045 | BE77: 37127 | BF77: 63783 | BG77: 4231 | BH77: 7424 | BI77: 15398 | BJ77: 63902.253 | BK77: 21329.747 | BL77: 87250 | BM77: =+SUM(C77:BL77) -> 683961
B78: Proprietor's jobs | C78: 3486.6806 | D78: 1136.2505 | E78: 2280.5324 | F78: 197.46757 | G78: 1251.0688 | H78: 445 | I78: 1103.2878 | J78: 4592.0027 | K78: 2647.6723 | L78: 3197.0372 | M78: 616 | N78: 44 | O78: 673 | P78: 97.33161 | Q78: 2302.6684 | R78: 96 | S78: 65 | T78: 366 | U78: 7453 | V78: 848 | W78: 4313.1166 | X78: 1641.8834 | Y78: 640.97065 | Z78: 533 | AA78: 320.02935 | AB78: 525 | AC78: 396 | AD78: 94 | AE78: 355.41392 | AF78: 81.586081 | AG78: 4356 | AH78: 19981 | AI78: 1256 | AJ78: 6402 | AK78: 11780 | AL78: 0 | AM78: 28588.737 | AN78: 12015.263 | AO78: 5105.6431 | AP78: 4368.039 | AQ78: 2637.2639 | AR78: 4459.5682 | AS78: 7115.4858 | AT78: 863 | AU78: 3904.3975 | AV78: 10546.603 | AW78: 195 | AX78: 1007.806 | AY78: 3331.194 | AZ78: 9051 | BA78: 14 | BB78: 1450 | BC78: 2100 | BD78: 9803 | BE78: 1392 | BF78: 4072 | BG78: 15730.536 | BH78: 17335.826 | BI78: 1133.199 | BJ78: 0 | BK78: 0 | BL78: 0 | BM78: =+SUM(C78:BL78) -> 231793.56
B79: Total jobs | C79: 6874.2336 | D79: 2240.1971 | E79: 3776.039 | F79: 326.96103 | G79: 2466.5693 | H79: 701 | I79: 4710.1021 | J79: 19603.952 | K79: 11303.312 | L79: 13648.634 | M79: 6478 | N79: 1305 | O79: 1162 | P79: 486.65805 | Q79: 6830.3419 | R79: 9481 | S79: 1295 | T79: 3695 | U79: 11397 | V79: 9464 | W79: 6542.4655 | X79: 2490.5345 | Y79: 1932.9167 | Z79: 2956 | AA79: 965.08331 | AB79: 3752 | AC79: 1013 | AD79: 400 | AE79: 3296.3218 | AF79: 756.67823 | AG79: 21689 | AH79: 84308 | AI79: 8974 | AJ79: 13805 | AK79: 13003 | AL79: 0 | AM79: 37380.668 | AN79: 15710.332 | AO79: 10754.054 | AP79: 9200.4335 | AQ79: 5554.8887 | AR79: 9393.222 | AS79: 14987.401 | AT79: 9533 | AU79: 13345.901 | AV79: 36050.099 | AW79: 2331 | AX79: 4755.4321 | AY79: 15718.568 | AZ79: 41572 | BA79: 16409 | BB79: 9343 | BC79: 18630 | BD79: 21848 | BE79: 38519 | BF79: 67855 | BG79: 19961.536 | BH79: 24759.826 | BI79: 16531.199 | BJ79: 63902.253 | BK79: 21329.747 | BL79: 87250 | BM79: =+SUM(C79:BL79) -> 915754.56
AX80: =+AX75*1000000/AX79 -> 189661.57
B81: Earnings (RIMS II for multiplier calculations) | C81: 150.39096 | D81: 49.009885 | E81: 63.454996 | F81: 5.4944642 | G81: 53.962341 | H81: 31.479864 | I81: 383.43947 | J81: 1595.9163 | K81: 920.1788 | L81: 1111.1065 | M81: 235.61937 | N81: 75.724265 | O81: 24.930259 | P81: 53.52504 | Q81: 383.27005 | R81: 870.64325 | S81: 130.67959 | T81: 242.53697 | U81: 302.10117 | V81: 638.8098 | W81: 122.66947 | X81: 46.696852 | Y81: 146.77936 | Z81: 154.71931 | AA81: 73.285262 | AB81: 286.43302 | AC81: 31.425502 | AD81: 12.250379 | AE81: 368.15318 | AF81: 84.510407 | AG81: 1348.9181 | AH81: 2821.9954 | AI81: 707.83897 | AJ81: 708.83084 | AK81: 206.20417 | AL81: 0 | AM81: 1942.1751 | AN81: 816.25653 | AO81: 739.46204 | AP81: 632.63315 | AQ81: 381.961 | AR81: 645.88952 | AS81: 1030.5522 | AT81: 976.10811 | AU81: 535.00999 | AV81: 1445.175 | AW81: 169.22639 | AX81: 287.94888 | AY81: 133.64024 | AZ81: 2049.6353 | BA81: 1481.1146 | BB81: 458.50754 | BC81: 320.40602 | BD81: 801.63314 | BE81: 2755.5666 | BF81: 2617.4861 | BG81: 366.38055 | BH81: 599.00469 | BI81: 164.55443 | BJ81: 4950.7132 | BK81: 1652.4842 | BL81: 5491.9292 | BM81: =+SUM(C81:BL81) -> 47888.437
B82: State taxes (for multiplier calculations) | C82: 13.109729 | D82: 3.6459777 | E82: 5.2030705 | F82: 0.44786418 | G82: 8.0197402 | H82: 4.0651307 | I82: 74.031267 | J82: 308.1261 | K82: 177.94522 | L82: 214.86703 | M82: 28.702418 | N82: 10.636998 | O82: 2.7879974 | P82: 25.087275 | Q82: 40.356702 | R82: 125.08111 | S82: 19.05467 | T82: 33.557272 | U82: 35.482623 | V82: 103.61785 | W82: 19.593509 | X82: 7.2275377 | Y82: 35.269555 | Z82: 33.232261 | AA82: 16.12209 | AB82: 101.85138 | AC82: 7.7648808 | AD82: 2.6086645 | AE82: 213.98603 | AF82: 23.576275 | AG82: 253.97659 | AH82: 2002.0327 | AI82: 115.69256 | AJ82: 335.24236 | AK82: 32.701912 | AL82: 76.584694 | AM82: 709.86377 | AN82: 262.38979 | AO82: 109.79346 | AP82: 94.121818 | AQ82: 57.340451 | AR82: 87.825278 | AS82: 148.6496 | AT82: 135.59548 | AU82: 60.10272 | AV82: 175.17915 | AW82: 30.974664 | AX82: 53.089502 | AY82: 19.70379 | AZ82: 294.04072 | BA82: 279.77956 | BB82: 39.318359 | BC82: 49.703737 | BD82: 88.91374 | BE82: 1299.1189 | BF82: 384.52473 | BG82: 42.825363 | BH82: 72.17788 | BI82: 19.7652 | BJ82: 541.70052 | BK82: 183.80308 | BL82: 527.91369 | BM82: =+SUM(C82:BL82) -> 10279.504
B83: State individual income tax | C83: 8.0309122 | D83: 2.0530837 | E83: 3.6646173 | F83: 0.30881504 | G83: 3.0559297 | H83: 2.4420489 | I83: 25.555093 | J83: 106.36305 | K83: 61.327162 | L83: 74.05192 | M83: 18.600401 | N83: 5.9317561 | O83: 2.0243331 | P83: 5.6805334 | Q83: 29.549226 | R83: 72.072446 | S83: 11.037169 | T83: 18.250093 | U83: 18.706851 | V83: 41.842152 | W83: 9.7107938 | X83: 3.1759367 | Y83: 11.159289 | Z83: 12.125326 | AA83: 4.2271131 | AB83: 22.069497 | AC83: 2.6230248 | AD83: 0.81862357 | AE83: 29.086505 | AF83: 6.4302895 | AG83: 98.767962 | AH83: 186.75572 | AI83: 52.148997 | AJ83: 55.685183 | AK83: 15.820277 | AL83: 0 | AM83: 124.09666 | AN83: 51.36815 | AO83: 53.49414 | AP83: 45.557595 | AQ83: 27.725812 | AR83: 39.242726 | AS83: 71.509983 | AT83: 77.54845 | AU83: 33.6212 | AV83: 100.6567 | AW83: 12.705668 | AX83: 23.83547 | AY83: 9.8379313 | AZ83: 142.69659 | BA83: 116.31812 | BB83: 32.31875 | BC83: 22.161396 | BD83: 48.579977 | BE83: 150.82839 | BF83: 162.46685 | BG83: 22.298074 | BH83: 37.244193 | BI83: 11.297604 | BJ83: 461.04954 | BK83: 153.89238 | BL83: 443.70252 | BM83: =+SUM(C83:BL83) -> 3497.207
B84: State GET | C84: 1.2539404 | D84: 0.40963305 | E84: 0.4411787 | F84: 0.039581564 | G84: 3.6173173 | H84: 0.43429808 | I84: 39.491872 | J84: 164.36942 | K84: 94.772673 | L84: 114.43703 | M84: 2.8484791 | N84: 1.2842259 | O84: 0.19880327 | P84: 0 | Q84: 2.7032912 | R84: 0 | S84: 0 | T84: 11.18682 | U84: 12.496819 | V84: 44.979609 | W84: 7.3371751 | X84: 2.8065807 | Y84: 18.365608 | Z84: 15.954704 | AA84: 8.9606683 | AB84: 0 | AC84: 3.9320819 | AD84: 1.3593988 | AE84: 0 | AF84: 0 | AG84: 117.902 | AH84: 1732.276 | AI84: 0 | AJ84: 2.3979659 | AK84: 0.76214058 | AL84: 0 | AM84: 441.13941 | AN84: 190.52559 | AO84: 41.08623 | AP84: 35.396739 | AQ84: 21.24473 | AR84: 34.567675 | AS84: 56.69017 | AT84: 41.631565 | AU84: 19.797981 | AV84: 52.776816 | AW84: 13.68995 | AX84: 20.581579 | AY84: 6.9338904 | AZ84: 107.99488 | BA84: 120.24495 | BB84: 0 | BC84: 20.132339 | BD84: 29.21132 | BE84: 252.05102 | BF84: 163.68294 | BG84: 14.943765 | BH84: 25.649131 | BI84: 0 | BJ84: 0 | BK84: 0 | BL84: 0 | BM84: =+SUM(C84:BL84) -> 4116.992
B85: State TAT | BE85: 810.038 | BM85: =+SUM(C85:BL85) -> 810.038
B86: State other taxes | C86: 3.8248767 | D86: 1.183261 | E86: 1.0972745 | F86: 0.099467582 | G86: 1.3464931 | H86: 1.1887837 | I86: 8.9843022 | J86: 37.393633 | K86: 21.84538 | L86: 26.378073 | M86: 7.2535377 | N86: 3.4210158 | O86: 0.5648611 | P86: 19.406741 | Q86: 8.1041847 | R86: 53.008663 | S86: 8.0175007 | T86: 4.1203584 | U86: 4.2789528 | V86: 16.796092 | W86: 2.5455406 | X86: 1.2450204 | Y86: 5.7446589 | Z86: 5.1522303 | AA86: 2.9343086 | AB86: 79.781883 | AC86: 1.2097742 | AD86: 0.43064217 | AE86: 184.89953 | AF86: 17.145985 | AG86: 37.306631 | AH86: 83.001025 | AI86: 63.543558 | AJ86: 277.15921 | AK86: 16.119494 | AL86: 76.584694 | AM86: 144.6277 | AN86: 20.496048 | AO86: 15.213085 | AP86: 13.167484 | AQ86: 8.3699093 | AR86: 14.014878 | AS86: 20.449451 | AT86: 16.415463 | AU86: 6.6835395 | AV86: 21.745635 | AW86: 4.579046 | AX86: 8.6724528 | AY86: 2.9319684 | AZ86: 43.349249 | BA86: 43.216485 | BB86: 6.9996086 | BC86: 7.4100017 | BD86: 11.122444 | BE86: 86.201462 | BF86: 58.374931 | BG86: 5.5835249 | BH86: 9.2845557 | BI86: 8.4675962 | BJ86: 80.650986 | BK86: 29.910693 | BL86: 84.211166 | BM86: =+SUM(C86:BL86) -> 1855.267
B88: Earnings (Labor Income) | C88: =C69+C70 -> 170.67937 | D88: =D69+D70 -> 55.621534 | E88: =E69+E70 -> 79.768018 | F88: =F69+F70 -> 6.9069821 | G88: =G69+G70 -> 61.242098 | H88: =H69+H70 -> 36.786 | I88: =I69+I70 -> 441.18625 | J88: =J69+J70 -> 1836.2647 | ... BM88: =BM69+BM70 -> 58544.997
B89: Earnings (Labor Income)/Output Ratio | C89: =C88/C75 -> 0.34920163 | D89: =D88/D75 -> 0.34920163 | E89: =E88/E75 -> 0.47170689 | F89: =F88/F75 -> 0.47170689 | G89: =G88/G75 -> 0.34920163 | H89: =H88/H75 -> 0.23860571 | I89: =I88/I75 -> 0.37968175 | J89: =J88/J75 -> 0.37968175 | ... BM89: =BM88/BM75 -> 0.40908926

Sheet fd, income ML
A1: 2022Detailed Output, Earnings, Employment, and Tax Multipliers for Hawaii
C3: Final demand multipliers | T3: Direct effect multipliers
C4: Output multipliers | F4: Earnings multipliers | I4: State tax multipliers | K4: State income tax multipliers | M4: State GET multipliers | O4: State TAT multipliers | Q4: State Other Taxes multipliers | T4: Earnings multipliers | DG4: Federal military consumption | DH4: Federal civilian consumption
B5: Industry | C5: type 1 | D5: type 2 | F5: type 1 | G5: type 2 | I5: type 1 | J5: type 2 | K5: type 1 | L5: type 2 | M5: type 1 | N5: type 2 | O5: type 1 | P5: type 2 | Q5: type 1 | R5: type 2 | T5: type 1 | U5: type 2
A6: 1 | B6: Crop production | C6: 1.3700296 | D6: 1.878914 | E6: =D6/C6 -> 1.3714404 | F6: 0.41330547 | G6: 0.54943284 | I6: 0.049811614 | J6: 0.079954802 | K6: 0.023577817 | L6: 0.033345632 | M6: 0.011720837 | N6: 0.024385689 | O6: 0.0010067034 | P6: 0.0021199625 | Q6: 0.013506257 | R6: 0.020103518 | T6: 1.3432417 | U6: 1.7856553
A7: =A6+1 -> 2 | B7: Animal production | C7: 1.3255298 | D7: 1.8234871 | E7: =D7/C7 -> 1.3756666 | F7: 0.40443071 | G7: 0.53763507 | I7: 0.038064329 | J7: 0.067560263 | K7: 0.019364517 | L7: 0.028922591 | M7: 0.0066948245 | N7: 0.019087729 | O7: 0.00065799961 | P7: 0.0017473541 | Q7: 0.011346988 | R7: 0.017802589 | T7: 1.3143988 | U7: 1.7473126
A8: =A7+1 -> 3 | B8: Commercial fishing | C8: 1.4311491 | D8: 2.0558189 | E8: =D8/C8 -> 1.4364812 | F8: 0.50734397 | G8: 0.67444411 | I8: 0.058773103 | J8: 0.095774705 | K8: 0.03082976 | L8: 0.042820024 | M8: 0.016477139 | N8: 0.032023598 | O8: 0.00064616984 | P8: 0.0020127263 | Q8: 0.010820034 | R8: 0.018918357 | T8: 1.3520516 | U8: 1.7973668
A9: =A8+1 -> 4 | B9: Forestry & logging | C9: 1.5222268 | D9: 2.2192086 | E9: =D9/C9 -> 1.4578699 | F9: 0.56607437 | G9: 0.75251811 | I9: 0.048089113 | J9: 0.089374041 | K9: 0.031976121 | L9: 0.045354384 | M9: 0.0054054892 | N9: 0.022751614 | O9: 9.1402346e-05 | P9: 0.0016161521 | Q9: 0.010616101 | R9: 0.01965189 | T9: 1.5085658 | U9: 2.005431
A10: =A9+1 -> 5 | B10: Support activities for agriculture | C10: 1.432057 | D10: 1.957929 | E10: =D10/C10 -> 1.3672144 | F10: 0.42710244 | G10: 0.56777402 | I10: 0.065141687 | J10: 0.096291116 | K10: 0.025662069 | L10: 0.035755954 | M10: 0.026738047 | N10: 0.039825678 | O10: 0.00049353912 | P10: 0.001643961 | Q10: 0.012248032 | R10: 0.019065523 | T10: 1.3880819 | U10: 1.8452641
A11: =A10+1 -> 6 | B11: Mining | C11: 1.4978496 | D11: 1.9308596 | E11: =D11/C11 -> 1.2890878 | F11: 0.3516819 | G11: 0.46751277 | I11: 0.056316205 | J11: 0.081965064 | K11: 0.026068495 | L11: 0.034379935 | M11: 0.014158335 | N11: 0.024934866 | O11: 0.0015339173 | P11: 0.0024811901 | Q11: 0.014555458 | R11: 0.020169073 | T11: 1.7223401 | U11: 2.2896146
A12: =A11+1 -> 7 | B12: Single family construction | C12: 1.4745155 | D12: 2.0447628 | E12: =D12/C12 -> 1.3867354 | F12: 0.46314317 | G12: 0.61568522 | I12: 0.10147814 | J12: 0.13525609 | K12: 0.031368155 | L12: 0.042313804 | M12: 0.053871173 | N12: 0.068063194 | O12: 0.0017761671 | P12: 0.0030236665 | Q12: 0.014462641 | R12: 0.021855422 | T12: 1.4035268 | U12: 1.865796
A13: =A12+1 -> 8 | B13: Construction of other buildings | C13: 1.5152142 | D13: 2.1186079 | E13: =D13/C13 -> 1.3982233 | F13: 0.49006396 | G13: 0.65147272 | I13: 0.10431306 | J13: 0.1400544 | K13: 0.033237908 | L13: 0.044819787 | M13: 0.054756076 | N13: 0.069773026 | O13: 0.0022917198 | P13: 0.0036117317 | Q13: 0.014027356 | R13: 0.021849852 | T13: 1.4851086 | U13: 1.9742478
A14: =A13+1 -> 9 | B14: Heavy and civil engineering construction | C14: 1.5218928 | D14: 2.130474 | E14: =D14/C14 -> 1.3998844 | F14: 0.49427718 | G14: 0.65707361 | I14: 0.10067601 | J14: 0.13672463 | K14: 0.033509372 | L14: 0.045190824 | M14: 0.050237778 | N14: 0.065383834 | O14: 0.0025399429 | P14: 0.0038713034 | Q14: 0.014388922 | R14: 0.02227867 | T14: 1.4978765 | U14: 1.991221
A15: =A14+1 -> 10 | B15: Maintenance & repairs | C15: 1.4720762 | D15: 2.0506088 | E15: =D15/C15 -> 1.3930046 | F15: 0.46987238 | G15: 0.62463078 | I15: 0.10408979 | J15: 0.13835852 | K15: 0.031724652 | L15: 0.042829335 | M15: 0.057285193 | N15: 0.071683416 | O15: 0.0019951487 | P15: 0.0032607736 | Q15: 0.013084799 | R15: 0.020584993 | T15: 1.4239192 | U15: 1.892905
A16: =A15+1 -> 11 | B16: Food processing | C16: 1.5958613 | D16: 2.113805 | E16: =D16/C16 -> 1.3245544 | F16: 0.42066327 | G16: 0.55921403 | I16: 0.064371558 | J16: 0.095051365 | K16: 0.031255458 | L16: 0.041197163 | M16: 0.015719985 | N16: 0.028610302 | O16: 0.0038267074 | P16: 0.0049597851 | Q16: 0.013569407 | R16: 0.020284115 | T16: 1.8387562 | U16: 2.4443738
A17: =A16+1 -> 12 | B17: Beverage manufacturing | C17: 1.5841104 | D17: 2.0003106 | E17: =D17/C17 -> 1.2627343 | F17: 0.33802929 | G17: 0.4493635 | I17: 0.05726688 | J17: 0.081920026 | K17: 0.025324344 | L17: 0.033313127 | M17: 0.015481775 | N17: 0.025839952 | O17: 0.0031189649 | P17: 0.0040294638 | Q17: 0.013341795 | R17: 0.018737484 | T17: 2.0832193 | U17: 2.7693539
A18: =A17+1 -> 13 | B18: Apparel and textile manufacturing | C18: 1.418927 | D18: 2.0151392 | E18: =D18/C18 -> 1.4201852 | F18: 0.48423133 | G18: 0.64371903 | I18: 0.067233143 | J18: 0.10254909 | K18: 0.037903784 | L18: 0.049347818 | M18: 0.013692009 | N18: 0.028530231 | O18: 0.0025253249 | P18: 0.0038296264 | Q18: 0.013112025 | R18: 0.020841419 | T18: 1.3667485 | U18: 1.8169044
... A40: =A39+1 -> 35 | B40: Other finance and insurance | C40: 1.8639635 | D40: 2.4525619 | E40: =D40/C40 -> 1.3157778 | F40: 0.47804751 | G40: 0.6354985 | I40: 0.088972378 | J40: 0.12383733 | K40: 0.035384707 | L40: 0.046682597 | M40: 0.018829262 | N40: 0.033477994 | O40: 0.0049164824 | P40: 0.0062041274 | Q40: 0.029841927 | R40: 0.037472614 | T40: 2.1087043 | U40: 2.8032327
A41: =A40+1 -> 36 | B41: Owner-occupied dwellings | C41: 1.3208347 | D41: 1.4300097 | E41: =D41/C41 -> 1.082656 | F41: 0.088669664 | G41: 0.11787414 | I41: 0.029176152 | J41: 0.035643006 | K41: 0.0061836243 | L41: 0.0082791902 | M41: 0.0092969883 | N41: 0.012014078 | O41: 0.00051303497 | P41: 0.00075187116 | Q41: 0.013182504 | R41: 0.014597867 | T41: NA | U41: NA
A42: =A41+1 -> 37 | B42: Real estate | C42: 1.3348462 | D42: 1.755656 | E42: =D42/C42 -> 1.3152496 | F42: 0.34177309 | G42: 0.45434037 | I42: 0.11351556 | J42: 0.13844175 | K42: 0.02239259 | L42: 0.030469851 | M42: 0.064575648 | N42: 0.075048545 | O42: 0.002720517 | P42: 0.0036411 | Q42: 0.023826805 | R42: 0.029282253 | T42: 1.4070702 | U42: 1.8705065
A43: =A42+1 -> 38 | B43: Rental & leasing and others | C43: 1.2754109 | D43: 1.6934186 | E43: =D43/C43 -> 1.3277436 | F43: 0.33949734 | G43: 0.45131508 | I43: 0.09608714 | J43: 0.12084735 | K43: 0.022264881 | L43: 0.030288358 | M43: 0.061744095 | N43: 0.072147257 | O43: 0.0023667457 | P43: 0.0032811989 | Q43: 0.0097114187 | R43: 0.015130541 | T43: 1.397701 | U43: 1.8580514
A44: =A43+1 -> 39 | B44: Legal services | C44: 1.6827391 | D44: 2.4278698 | E44: =D44/C44 -> 1.4428082 | F44: 0.60517985 | G44: 0.80450348 | I44: 0.11150755 | J44: 0.15564451 | K44: 0.04285265 | L44: 0.05715511 | M44: 0.040395873 | N44: 0.058940301 | O44: 0.01225248 | P44: 0.013882562 | Q44: 0.016006543 | R44: 0.025666541 | T44: 1.5057398 | U44: 2.0016742
A45: =A44+1 -> 40 | B45: Architectural and engineering services | C45: 1.5996094 | D45: 2.3196113 | E45: =D45/C45 -> 1.450111 | F45: 0.58477076 | G45: 0.77737239 | I45: 0.099691003 | J45: 0.1423395 | K45: 0.041663198 | L45: 0.055483321 | M45: 0.040000426 | N45: 0.057919461 | O45: 0.0019900351 | P45: 0.0035651445 | Q45: 0.016037344 | R45: 0.025371568 | T45: 1.4549602 | U45: 1.9341698
A46: =A45+1 -> 41 | B46: Computer systems design services | C46: 1.0896405 | D46: 1.6168268 | E46: =D46/C46 -> 1.4838167 | F46: 0.42816991 | G46: 0.56919308 | I46: 0.067028891 | J46: 0.098256173 | K46: 0.03095735 | L46: 0.041076462 | M46: 0.024966566 | N46: 0.038086907 | O46: 0.0012993875 | P46: 0.0024526846 | Q46: 0.0098055874 | R46: 0.016640118 | T46: 1.0653238 | U46: 1.4162016
A47: =A46+1 -> 42 | B47: R&D in the physical, engineering, & life sciences | C47: 1.4706667 | D47: 2.1318293 | E47: =D47/C47 -> 1.4495666 | F47: 0.53698272 | G47: 0.71384475 | I47: 0.087208129 | J47: 0.12637134 | K47: 0.03381565 | L47: 0.046506379 | M47: 0.03470436 | N47: 0.051159035 | O47: 0.0038310597 | P47: 0.0052774497 | Q47: 0.014857059 | R47: 0.023428481 | T47: 1.3360595 | U47: 1.7761075
A48: =A47+1 -> 43 | B48: Other professional services | C48: 1.6171634 | D48: 2.3443143 | E48: =D48/C48 -> 1.4496459 | F48: 0.59057705 | G48: 0.78509105 | I48: 0.10068985 | J48: 0.14376181 | K48: 0.040914547 | L48: 0.054871892 | M48: 0.037579736 | N48: 0.055676693 | O48: 0.0071982443 | P48: 0.0087889933 | Q48: 0.014997326 | R48: 0.024424231 | T48: 1.4694068 | U48: 1.9533745
A49: =A48+1 -> 44 | B49: Management of companies and enterprises | C49: 1.3571027 | D49: 2.1548652 | E49: =D49/C49 -> 1.5878424 | F49: 0.64792639 | G49: 0.86132913 | I49: 0.097204103 | J49: 0.14445866 | K49: 0.050236151 | L49: 0.065548857 | M49: 0.03240405 | N49: 0.052258353 | O49: 0.00099192365 | P49: 0.002737146 | Q49: 0.013571978 | R49: 0.023914305 | T49: 1.2209162 | U49: 1.6230404
A50: =A49+1 -> 45 | B50: Travel arrangement and reservation services | C50: 1.2316069 | D50: 2.0513585 | E50: =D50/C50 -> 1.6655952 | F50: 0.66578548 | G50: 0.88507033 | I50: 0.082282795 | J50: 0.13083985 | K50: 0.042343446 | L50: 0.058078223 | M50: 0.027783923 | N50: 0.04818548 | O50: 0.0017849651 | P50: 0.0035782917 | Q50: 0.010370461 | R50: 0.020997857 | T50: 1.1192 | U50: 1.4878227
A51: =A50+1 -> 46 | B51: Administrative and support services | C51: 1.2295735 | D51: 2.0519027 | E51: =D51/C51 -> 1.6687923 | F51: 0.66787897 | G51: 0.88785334 | I51: 0.088833562 | J51: 0.1375433 | K51: 0.046553094 | L51: 0.062337347 | M51: 0.028800022 | N51: 0.049265729 | O51: 0.0017828773 | P51: 0.0035818429 | Q51: 0.011697568 | R51: 0.022358381 | T51: 1.1227192 | U51: 1.492501
A52: =A51+1 -> 47 | B52: Waste management and remediation services | C52: 1.5621899 | D52: 2.12704 | E52: =D52/C52 -> 1.3615758 | F52: 0.45875962 | G52: 0.60985789 | I52: 0.083089538 | J52: 0.11654779 | K52: 0.034259962 | L52: 0.045102013 | M52: 0.032292499 | N52: 0.046350196 | O52: 0.0029325148 | P52: 0.0041682069 | Q52: 0.013604561 | R52: 0.020927371 | T52: 1.7283784 | U52: 2.2976417
A53: =A52+1 -> 48 | B53: Colleges, universities, and professional schools | C53: 1.0525687 | D53: 1.4647983 | E53: =D53/C53 -> 1.3916416 | F53: 0.3348045 | G53: 0.44507659 | I53: 0.062413171 | J53: 0.086831128 | K53: 0.027500666 | L53: 0.035413236 | M53: 0.024250551 | N53: 0.034509911 | O53: 0.00038672429 | P53: 0.0012885371 | Q53: 0.01027523 | R53: 0.015619444 | T53: 1.0486854 | U53: 1.3940832
... A55: =A54+1 -> 50 | B55: Ambulatory health care services | C55: 1.1607409 | D55: 1.7506545 | E55: =D55/C55 -> 1.5082216 | F55: 0.47911575 | G55: 0.63691856 | I55: 0.06965984 | J55: 0.1046027 | K55: 0.033366579 | L55: 0.044689715 | M55: 0.025624898 | N55: 0.040306364 | O55: 0.0003133927 | P55: 0.0016039151 | Q55: 0.01035497 | R55: 0.018002708 | T55: 1.151725 | U55: 1.5310602
A56: =A55+1 -> 51 | B56: Hospitals | C56: 1.6391653 | D56: 2.2345214 | F56: 0.48353595 | G56: 0.64279462 | I56: 0.096290535 | J56: 0.13155577 | K56: 0.03623226 | L56: 0.04765986 | M56: 0.038367664 | N56: 0.053184578 | O56: 0.0055544722 | P56: 0.0068569006 | Q56: 0.016136138 | R56: 0.023854433 | T56: 1.7797372 | U56: 2.3659161
A57: =A56+1 -> 52 | B57: Nursing and residential care facilities | C57: 1.3623604 | D57: 2.176905 | F57: 0.66155646 | G57: 0.87944843 | I57: 0.070304472 | J57: 0.1185531 | K57: 0.046425385 | L57: 0.062060216 | M57: 0.0082568184 | N57: 0.028528786 | O57: 0.0018995495 | P57: 0.0036814851 | Q57: 0.013722718 | R57: 0.02428261 | T57: 1.1930084 | U57: 1.5859407
A58: =A57+1 -> 53 | B58: Social assistance | C58: 1.1670253 | D58: 1.6657918 | F58: 0.40508788 | G58: 0.53850869 | I58: 0.065232532 | J58: 0.094776396 | K58: 0.028123258 | L58: 0.037696863 | M58: 0.026091422 | N58: 0.038504464 | O58: 0.0007893872 | P58: 0.0018805118 | Q58: 0.010228466 | R58: 0.016694557 | T58: 1.1536798 | U58: 1.5336587
A59: =A58+1 -> 54 | B59: Arts and entertainment | C59: 1.0701682 | D59: 1.81337 | F59: 0.60361332 | G59: 0.80242099 | I59: 0.068616813 | J59: 0.11263953 | K59: 0.036799794 | L59: 0.051065231 | M59: 0.022631317 | N59: 0.041127743 | O59: 0.00023509784 | P59: 0.0018609607 | Q59: 0.0089506034 | R59: 0.018585596 | T59: 1.0434067 | U59: 1.3870659
A60: =A59+1 -> 55 | B60: Accommodation | C60: 1.5887531 | D60: 2.1022555 | F60: 0.41705614 | G60: 0.55441884 | I60: 0.14493547 | J60: 0.1753522 | K60: 0.025852527 | L60: 0.035708982 | M60: 0.03379446 | N60: 0.046574243 | O60: 0.069595049 | P60: 0.070718411 | Q60: 0.015693436 | R60: 0.022350566 | T60: 1.8428232 | U60: 2.4497802
A61: =A60+1 -> 56 | B61: Eating and drinking | C61: 1.5189485 | D61: 2.1393386 | F61: 0.50386815 | G61: 0.66982348 | I61: 0.083250679 | J61: 0.11999878 | K61: 0.0324781 | L61: 0.044386219 | M61: 0.033540958 | N61: 0.048980908 | O61: 0.0028233992 | P61: 0.0041805934 | Q61: 0.014408223 | R61: 0.022451063 | T61: 1.4498608 | U61: 1.9273908
A62: =A61+1 -> 57 | B62: Repair and maintenance | C62: 1.1186764 | D62: 1.6430934 | F62: 0.42592077 | G62: 0.56620316 | I62: 0.054358261 | J62: 0.085421509 | K62: 0.026253679 | L62: 0.036319637 | M62: 0.019256446 | N62: 0.032307867 | O62: 0.0014055224 | P62: 0.0025527614 | Q62: 0.0074426137 | R62: 0.014241243 | T62: 1.089847 | U62: 1.4488019
A63: =A62+1 -> 58 | B63: Personal and laundry services | C63: 1.3578701 | D63: 2.1166241 | F63: 0.61624447 | G63: 0.81921237 | I63: 0.086844964 | J63: 0.1317889 | K63: 0.039168647 | L63: 0.053732601 | M63: 0.032081802 | N63: 0.050965281 | O63: 0.0029726832 | P63: 0.0046325687 | Q63: 0.012621832 | R63: 0.022458445 | T63: 1.2150446 | U63: 1.6152348
...

Sheet job ML
B1: Job multipliers for years 2022-2032
D2: Direct effect multipliers | J2: Final demand multipliers
D3: w&s job/w&s job multipliers | G3: total job/total job multipliers | J3: W&S job multipliers | M3: Total jobs multipliers | P3: W&S job multipliers | S3: Total jobs multipliers | V3: W&S job multipliers | Y3: Total jobs multipliers | AB3: W&S job multipliers | AE3: Total jobs multipliers | AH3: W&S job multipliers | AK3: Total jobs multipliers | AN3: W&S job multipliers | AQ3: Total jobs multipliers | AT3: W&S job multipliers | AW3: Total jobs multipliers | AZ3: W&S job multipliers | BC3: Total jobs multipliers | BF3: W&S job multipliers | BI3: Total jobs multipliers | BL3: W&S job multipliers | BO3: Total jobs multipliers | BR3: W&S job multipliers | BU3: Total jobs multipliers
B4: Industry | D4: Type 1 | E4: Type 2 | G4: Type 1 | H4: Type 2 | J4: type 1 | K4: type 2 | M4: type 1 | N4: type 2 | P4: type 1 | Q4: type 2 | S4: type 1 | T4: type 2 | V4: type 1 | W4: type 2 | Y4: type 1 | Z4: type 2 | AB4: type 1 | AC4: type 2 | AE4: type 1 | AF4: type 2 | AH4: type 1 | AI4: type 2 | AK4: type 1 | AL4: type 2 | AN4: type 1 | AO4: type 2 | AQ4: type 1 | AR4: type 2 | AT4: type 1 | AU4: type 2 | AW4: type 1 | AX4: type 2 | AZ4: type 1 | BA4: type 2 | BC4: type 1 | BD4: type 2 | BF4: type 1 | BG4: type 2 | BI4: type 1 | BJ4: type 2 | BL4: type 1 | BM4: type 2 | BO4: type 1 | BP4: type 2 | BR4: type 1 | BS4: type 2 | BU4: type 1 | BV4: type 2
D5: 2022 | E5: 2022 | G5: 2022 | H5: 2022 | J5: 2022 | K5: 2022 | M5: 2022 | N5: 2022 | P5: 2023 | Q5: 2023 | S5: 2023 | T5: 2023 | V5: 2024 | W5: 2024 | Y5: 2024 | Z5: 2024 | AB5: 2025 | AC5: 2025 | AE5: 2025 | AF5: 2025 | AH5: 2026 | AI5: 2026 | AK5: 2026 | AL5: 2026 | AN5: 2027 | AO5: 2027 | AQ5: 2027 | AR5: 2027 | AT5: 2028 | AU5: 2028 | AW5: 2028 | AX5: 2028 | AZ5: 2029 | BA5: 2029 | BC5: 2029 | BD5: 2029 | BF5: 2030 | BG5: 2030 | BI5: 2030 | BJ5: 2030 | BL5: 2031 | BM5: 2031 | BO5: 2031 | BP5: 2031 | BR5: 2032 | BS5: 2032 | BU5: 2032 | BV5: 2032
A6: 1 | B6: Crop production | D6: 1.2263863 | E6: 1.5286101 | G6: 1.1951236 | H6: 1.4012304 | J6: 8.4997987 | K6: 10.594441 | M6: 16.808631 | N6: 19.707388 | P6: 7.8711865 | Q6: 9.9193666 | S6: 15.563229 | T6: 18.417679 | V6: 7.2984074 | W6: 9.3065027 | Y6: 14.43212 | Z6: 17.254066 | AB6: 7.1611977 | AC6: 9.1044286 | AE6: 14.168715 | AF6: 16.900212 | AH6: 7.0268604 | AI6: 8.9074044 | AK6: 13.910527 | AL6: 16.554585 | AN6: 6.8953249 | AO6: 8.7152835 | AQ6: 13.657439 | AR6: 16.216963 | AT6: 6.7665225 | AU6: 8.5279244 | AW6: 13.409336 | AX6: 15.887132 | AZ6: 6.6403868 | BA6: 8.3451901 | BC6: 13.166107 | BD6: 15.564883 | BF6: 6.5168531 | BG6: 8.1669479 | BI6: 12.927643 | BJ6: 15.250015 | BL6: 6.3958586 | BM6: 7.9930699 | BO6: 12.693837 | BP6: 14.942332 | BR6: 6.2773426 | BS6: 7.8234319 | BU6: 12.464587 | BV6: 14.641645
A7: =A6+1 -> 2 | B7: Animal production | D7: 1.2320225 | E7: 1.5277567 | G7: 1.1854351 | H7: 1.3871162 | J7: 8.5388615 | K7: 10.588526 | M7: 16.672369 | N7: 19.508882 | P7: 8.3056027 | Q7: 10.309803 | S7: 16.206234 | T7: 18.999391 | V7: 8.0831599 | W7: 10.048136 | Y7: 15.761453 | Z7: 18.522804 | AB7: 7.9364555 | AC7: 9.8379601 | AE7: 15.48317 | AF7: 18.156015 | AH7: 7.7926354 | AI7: 9.6327991 | AK7: 15.210086 | AL7: 17.797369 | AN7: 7.6516349 | AO7: 9.4325142 | AQ7: 14.942093 | AR7: 17.446658 | AT7: 7.5133911 | AU7: 9.236971 | AW7: 14.679088 | AX7: 17.103679 | AZ7: 7.3778426 | BA7: 9.0460393 | BC7: 14.420967 | BD7: 16.768235 | BF7: 7.2449299 | BG7: 8.8595929 | BI7: 14.167631 | BJ7: 16.440136 | BL7: 7.1145949 | BM7: 8.6775097 | BO7: 13.918982 | BP7: 16.119196 | BR7: 6.9867808 | BS7: 8.4996714 | BU7: 13.674925 | BV7: 15.805236
A8: =A7+1 -> 3 | B8: Commercial fishing | D8: 1.1992215 | E8: 1.4899646 | G8: 1.1088648 | H8: 1.2682189 | J8: 10.6055 | K8: 13.176731 | M8: 24.760448 | N8: 28.318753 | P8: 11.540288 | Q8: 14.054486 | S8: 27.201616 | T8: 30.705532 | V8: 12.589994 | W8: 15.054987 | Y8: 29.928823 | Z8: 33.392839 | AB8: 12.354217 | AC8: 14.739587 | AE8: 29.395936 | AF8: 32.748925 | AH8: 12.123313 | AI8: 14.431733 | AK8: 28.87317 | AL8: 32.118825 | AN8: 11.897165 | AO8: 14.131215 | AQ8: 28.360309 | AR8: 31.502196 | AT8: 11.675661 | AU8: 13.83783 | AW8: 27.857144 | AX8: 30.898707 | AZ8: 11.458689 | BA8: 13.551383 | BC8: 27.363471 | BD8: 30.308035 | BF8: 11.246144 | BG8: 13.271682 | BI8: 26.879092 | BJ8: 29.729868 | BL8: 11.037922 | BM8: 12.998543 | BO8: 26.403811 | BP8: 29.163901 | BR8: 10.833922 | BS8: 12.731789 | BU8: 25.937439 | BV8: 28.609839
A9: =A8+1 -> 4 | B9: Forestry & logging | D9: 1.491963 | E9: 1.8163628 | G9: 1.4850204 | H9: 1.6628214 | J9: 13.194405 | K9: 16.063283 | M9: 33.159831 | N9: 37.130047 | P9: 15.531878 | Q9: 18.337121 | S9: 39.070105 | T9: 42.979636 | V9: 18.293974 | W9: 21.044316 | Y9: 46.052512 | Z9: 49.917525 | AB9: 17.988098 | AC9: 20.6496 | AE9: 45.284024 | AF9: 49.025157 | AH9: 17.687371 | AI9: 20.263015 | AK9: 44.528416 | AL9: 48.14979 | AN9: 17.391706 | AO9: 19.884371 | AQ9: 43.78547 | AR9: 47.291063 | AT9: 17.101017 | AU9: 19.513481 | AW9: 43.054971 | AX9: 46.448626 | AZ9: 16.815217 | BA9: 19.150162 | BC9: 42.336709 | BD9: 45.622137 | BF9: 16.534225 | BG9: 18.794239 | BI9: 41.630477 | BJ9: 44.811261 | BL9: 16.257957 | BM9: 18.445541 | BO9: 40.936073 | BP9: 44.015672 | BR9: 15.986333 | BS9: 18.103899 | BU9: 40.253295 | BV9: 43.235053
A10: =A9+1 -> 5 | B10: Support activities for agriculture | D10: 1.2574079 | E10: 1.5697205 | G10: 1.2058209 | H10: 1.418808 | J10: 8.7148022 | K10: 10.879368 | M10: 16.959082 | N10: 19.954605 | P10: 8.2736325 | Q10: 10.390185 | S10: 16.09775 | T10: 19.047487 | V10: 7.872688 | W10: 9.9478176 | Y10: 15.320704 | Z10: 18.236852 | AB10: 7.7237346 | AC10: 9.7318345 | AE10: 15.041787 | AF10: 17.864468 | AH10: 7.5779307 | AI10: 9.5212511 | AK10: 14.768401 | AL10: 17.500723 | AN10: 7.4351978 | AO10: 9.3159104 | AQ10: 14.500419 | AR10: 17.145385 | AT10: 7.2954596 | AU10: 9.1156607 | AW10: 14.237718 | AX10: 16.798227 | AZ10: 7.1586422 | BA10: 8.9203553 | BC10: 13.98018 | BD10: 16.459032 | BF10: 7.0246739 | BG10: 8.7298523 | BI10: 13.727687 | BJ10: 16.127585 | BL10: 6.8934851 | BM10: 8.5440145 | BO10: 13.480128 | BP10: 15.803682 | BR10: 6.7650082 | BS10: 8.3627091 | BU10: 13.23739 | BV10: 15.487123
A11: =A10+1 -> 6 | B11: Mining | D11: 2.2372322 | E11: 3.3106048 | G11: 1.7560701 | H11: 2.2985384 | J11: 3.7149184 | K11: 5.497251 | M11: 7.9846911 | N11: 10.451245 | P11: 3.4998588 | Q11: 5.2426565 | S11: 7.4684544 | T11: 9.8973076 | V11: 3.3268446 | W11: 5.0355343 | Y11: 7.0625841 | Z11: 9.4637795 | AB11: 3.2226497 | AC11: 4.8761461 | AE11: 6.8453526 | AF11: 9.1695856 | AH11: 3.1219651 | AI11: 4.7221212 | AK11: 6.6352352 | AL11: 8.885066 | AN11: 3.0246655 | AO11: 4.5732695 | AQ11: 6.4319877 | AR11: 8.6098884 | AT11: 2.9306304 | AU11: 4.4294084 | AW11: 6.2353744 | AX11: 8.3437321 | AZ11: 2.8397436 | BA11: 4.2903619 | BC11: 6.0451683 | BD11: 8.0862881 | BF11: 2.7518934 | BG11: 4.1559602 | BI11: 5.8611502 | BJ11: 7.8372582 | BL11: 2.6669721 | BM11: 4.0260402 | BO11: 5.6831088 | BP11: 7.5963547 | BR11: 2.5848761 | BS11: 3.9004444 | BU11: 5.5108403 | BV11: 7.3633004
A12: =A11+1 -> 7 | B12: Single family construction | D12: 1.5870662 | E12: 2.3432588 | G12: 1.6561498 | H12: 2.4575102 | J12: 4.9262514 | K12: 7.2734724 | M12: 6.7131707 | N12: 9.9614692 | P12: 4.7970504 | Q12: 7.0922066 | S12: 6.5748735 | T12: 9.773522 | V12: 4.6760056 | W12: 6.9262435 | Y12: 6.4517075 | Z12: 9.6139324 | AB12: 4.517231 | AC12: 6.694783 | AE12: 6.2350566 | AF12: 9.2959268 | AH12: 4.3639411 | AI12: 6.4712471 | AK12: 6.0258097 | AL12: 8.9886968 | AN12: 4.2159428 | AO12: 6.255358 | AQ12: 5.823709 | AR12: 8.6918686 | AT12: 4.0730503 | AU12: 6.0468477 | AW12: 5.6285062 | AX12: 8.405082 | AZ12: 3.9350841 | BA12: 5.8454581 | BC12: 5.4399615 | BD12: 8.1279893 | BF12: 3.8018714 | BG12: 5.6509401 | BI12: 5.257844 | BJ12: 7.8602552 | BL12: 3.6732455 | BM12: 5.4630536 | BO12: 5.0819304 | BP12: 7.6015562 | BR12: 3.5490455 | BS12: 5.2815672 | BU12: 4.9120059 | BV12: 7.3515805
A13: =A12+1 -> 8 | B13: Construction of other buildings | D13: 1.6353525 | E13: 2.4354998 | G13: 1.7389435 | H13: 2.586884 | J13: 5.076132 | K13: 7.5597882 | M13: 7.0487733 | N13: 10.485883 | P13: 4.9525491 | Q13: 7.3811142 | S13: 6.9195858 | T13: 10.30416 | V13: 4.8374223 | W13: 7.2184582 | Y13: 6.8068186 | Z13: 10.152852 | AB13: 4.6727516 | AC13: 6.9768765 | AE13: 6.5776972 | AF13: 9.8164843 | AH13: 4.5137748 | AI13: 6.7435707 | AK13: 6.3564083 | AL13: 9.4915171 | AN13: 4.3602918 | AO13: 6.5182506 | AQ13: 6.1426799 | AR13: 9.1775551 | AT13: 4.2121095 | AU13: 6.3006364 | AW13: 5.9362495 | AX13: 8.8742174 | AZ13: 4.0690416 | BA13: 6.0904585 | BC13: 5.7368638 | BD13: 8.5811366 | BF13: 3.9309087 | BG13: 5.8874568 | BI13: 5.5442785 | BJ13: 8.2979582 | BL13: 3.7975377 | BM13: 5.6913808 | BO13: 5.358258 | BP13: 8.0243403 | BR13: 3.6687618 | BS13: 5.5019885 | BU13: 5.178575 | BV13: 7.759953
A14: =A13+1 -> 9 | B14: Heavy and civil engineering construction | D14: 1.6392062 | E14: 2.4462326 | G14: 1.7597604 | H14: 2.6149908 | J14: 5.0880939 | K14: 7.5931028 | M14: 7.133154 | N14: 10.599814 | P14: 4.9353608 | Q14: 7.3848049 | S14: 6.9731835 | T14: 10.386856 | V14: 4.7935202 | W14: 7.1950265 | Y14: 6.8338105 | Z14: 10.208611 | AB14: 4.6304938 | AC14: 6.954428 | AE14: 6.6039464 | AF14: 9.8705784 | AH14: 4.4731019 | AI14: 6.7220679 | AK14: 6.3819363 | AL14: 9.5439985 | AN14: 4.3211461 | AO14: 6.4976575 | AQ14: 6.1675075 | AR14: 9.2284743 | AT14: 4.1744357 | AU14: 6.2809183 | AW14: 5.9603968 | AX14: 8.9236233 | AZ14: 4.0327864 | BA14: 6.0715819 | BC14: 5.7603505 | BD14: 8.6290764 | BF14: 3.8960206 | BG14: 5.8693897 | BI14: 5.5671239 | BJ14: 8.3444778 | BL14: 3.7639671 | BM14: 5.674092 | BO14: 5.3804806 | BP14: 8.069484 | BR14: 3.6364609 | BS14: 5.4854484 | BU14: 5.2001929 | BV14: 7.8037638
A15: =A14+1 -> 10 | B15: Maintenance & repairs | D15: 1.6102018 | E15: 2.3773815 | G15: 1.6958354 | H15: 2.508839 | J15: 4.9980641 | K15: 7.3793889 | M15: 6.8740353 | N15: 10.16953 | P15: 4.832533 | Q15: 7.1610365 | S15: 6.6942114 | T15: 9.9393344 | V15: 4.6780107 | W15: 6.9609433 | Y15: 6.5346992 | Z15: 9.7428694 | AB15: 4.5192455 | AC15: 6.728436 | AE15: 6.3154227 | AF15: 9.4207656 | AH15: 4.3659574 | AI15: 6.5038814 | AK15: 6.1036267 | AL15: 9.1095628 | AN15: 4.2179543 | AO15: 6.2870009 | AQ15: 5.8990515 | AR15: 8.8088839 | AT15: 4.0750506 | AU15: 6.0775262 | AW15: 5.7014469 | AX15: 8.5183649 | AZ15: 3.9370677 | BA15: 5.8751983 | BC15: 5.5105714 | BD15: 8.2376546 | BF15: 3.8038331 | BG15: 5.6797677 | BI15: 5.3261918 | BJ15: 7.9664146 | BL15: 3.6751808 | BM15: 5.4909938 | BO15: 5.1480836 | BP15: 7.7043181 | BR15: 3.5509503 | BS15: 5.3086445 | BU15: 4.9760298 | BV15: 7.45105
A16: =A15+1 -> 11 | B16: Food processing | D16: 1.4953643 | E16: 1.8699301 | G16: 1.6607991 | H16: 2.1298661 | J16: 8.5112293 | K16: 10.643161 | M16: 10.44618 | N16: 13.396542 | P16: 8.7597298 | Q16: 10.844372 | S16: 10.696974 | T16: 13.602239 | V16: 9.0371695 | W16: 11.081014 | Y16: 10.98688 | Z16: 13.859063 | AB16: 8.8469525 | AC16: 10.824777 | AE16: 10.75266 | AF16: 13.532784 | AH16: 8.6613831 | AI16: 10.575405 | AK16: 10.524218 | AL16: 13.215346 | AN16: 8.4803261 | AO16: 10.332684 | AQ16: 10.301386 | AR16: 12.906475 | AT16: 8.3036506 | AU16: 10.09641 | AW16: 10.084001 | AX16: 12.605907 | AZ16: 8.1312304 | BA16: 9.8663832 | BC16: 9.8719065 | BD16: 12.313386 | BF16: 7.9629434 | BG16: 9.6424138 | BI16: 9.6649503 | BJ16: 12.028666 | BL16: 7.7986716 | BM16: 9.424317 | BO16: 9.4629853 | BP16: 11.751509 | BR16: 7.6383012 | BS16: 9.2119145 | BU16: 9.2658696 | BV16: 11.481684
A17: =A16+1 -> 12 | B17: Beverage manufacturing | D17: 1.9405115 | E17: 2.574518 | G17: 2.2625668 | H17: 3.1103801 | J17: 5.2434312 | K17: 6.956572 | M17: 6.326976 | N17: 8.6977765 | P17: 5.0095769 | Q17: 6.6847177 | S17: 6.1036747 | T17: 8.4382376 | V17: 4.7999821 | W17: 6.4423388 | Y17: 5.9133873 | Z17: 8.2213661 | AB17: 4.6401272 | AC17: 6.2294335 | AE17: 5.7198991 | AF17: 7.9539033 | AH17: 4.4858467 | AI17: 6.0238833 | AK17: 5.5330693 | AL17: 7.6955596 | AN17: 4.3369392 | AO17: 5.825425 | AQ17: 5.3526593 | AR17: 7.4460119 | AT17: 4.1932106 | AU17: 5.6338047 | AW17: 5.1784397 | AX17: 7.2049491 | AZ17: 4.0544742 | BA17: 5.4487781 | BC17: 5.0101895 | BD17: 6.9720712 | BF17: 3.9205503 | BG17: 5.2701099 | BI17: 4.8476959 | BJ17: 6.7470895 | BL17: 3.7912656 | BM17: 5.0975735 | BO17: 4.6907537 | BP17: 6.5297256 | BR17: 3.6664536 | BS17: 4.9309504 | BU17: 4.5391655 | BV17: 6.3197114
A18: =A17+1 -> 13 | B18: Apparel and textile manufacturing | D18: 1.2675024 | E18: 1.6206411 | G18: 1.1761992 | H18: 1.3818592 | J18: 8.8083617 | K18: 11.262458 | M18: 19.423365 | N18: 22.819567 | P18: 8.6751718 | Q18: 11.074833 | S18: 19.173054 | T18: 22.517346 | V18: 8.5516891 | W18: 10.904386 | Y18: 18.943745 | Z18: 22.249955 | AB18: 8.2601096 | AC18: 10.536811 | AE18: 18.300086 | AF18: 21.500326 | AH18: 7.9786197 | AI18: 10.181877 | AK18: 17.678544 | AL18: 20.776339 | AN18: 7.7068657 | AO18: 9.8391409 | AQ18: 17.078351 | AR18: 20.077106 | AT18: 7.4445067 | AU18: 9.5081764 | AW18: 16.498768 | AX18: 19.401769 | AZ18: 7.1912137 | BA18: 9.1885721 | BC18: 15.939081 | BD18: 18.749502 | BF18: 6.9466696 | BG18: 8.8799313 | BI18: 15.398601 | BJ18: 18.119507 | BL18: 6.7105683 | BM18: 8.5818712 | BO18: 14.876663 | BP18: 17.511014 | BR18: 6.4826146 | BS18: 8.2940227 | BU18: 14.372626 | BV18: 16.923281
