Workbook

Sheet I-O condensed 2022
A1: 2022 Condensed Input-Output Transactions Table for Hawaii (in $million except for employment, which is number of jobs)
B3: Industry | C3: Agriculture | D3: Mining and Construction | E3: Food processing | F3: Other manufacturing | G3: Transportation | H3: Information | I3: Utilities | J3: Wholesale trade | K3: Retail trade | L3: Finance and insurance | M3: Real estate and rentals | N3: Professional services | O3: Business services | P3: Educational services | Q3: Health services | R3: Arts and entertainment | S3: Accommodation | T3: Eating and drinking | U3: Other services | V3: Government | W3: Total Interindustry demand | X3: PCE | Y3: Visitor expenditures | Z3: Gross private investment* | AA3: State and local government | AB3: Federal government: military | AC3: Federal government: civilian | AD3: Exports | AE3: Total Output | AL3: PCE | AM3: Visitor expenditures | AN3: Gross private investment* | AO3: State and local government | AR3: Federal government: defense | AS3: Federal government: nondefense | AT3: Exports | AU3: Total Output
A4: 1 | B4: Agriculture | C4: 71.410328 | D4: 12.055218 | E4: 77.153207 | F4: 3.8965907 | G4: 0.10233403 | H4: 0.007122563 | I4: 0.033714698 | J4: 0.19059885 | K4: 0.17256993 | L4: 0.0011107979 | M4: 36.418072 | N4: 3.4738238 | O4: 0.73247852 | P4: 0.031974831 | Q4: 6.0488268 | R4: 0.19887016 | S4: 0.18409218 | T4: 70.033534 | U4: 1.4338049 | V4: 0.25847362 | W4: 283.83675 | X4: 265.75341 | Y4: 28.300479 | Z4: 0 | AA4: 8.0341178 | AB4: 0 | AC4: 0 | AD4: 421.25262 | AE4: 1007.1773 | AJ4: 1 | AK4: Agriculture | AL4: 265.75341 | AM4: 28.300479 | AN4: 0 | AO4: 8.0341178 | AP4: 1 | AQ4: Agriculture | AR4: 0 | AS4: 0 | AT4: 421.25262 | AU4: 1007.1773
A5: 2 | B5: Mining and construction | C5: 22.833933 | D5: 23.819747 | E5: 7.8507114 | F5: 3.6988039 | G5: 141.76209 | H5: 24.290164 | I5: 194.61932 | J5: 13.707423 | K5: 43.668212 | L5: 45.350493 | M5: 1168.5031 | N5: 41.310943 | O5: 21.544899 | P5: 11.290385 | Q5: 39.887551 | R5: 1.9167031 | S5: 490.13385 | T5: 179.89718 | U5: 17.713442 | V5: 46.521397 | W5: 2540.3204 | X5: 410.53387 | Y5: 0 | Z5: 6290.5391 | AA5: 2323.5872 | AB5: 257.05031 | AC5: 59.046419 | AD5: 427.09417 | AE5: 12308.171 | AJ5: 2 | AK5: Mining and construction | AL5: 410.53387 | AM5: 0 | AN5: 6290.5391 | AO5: 2323.5872 | AP5: 2 | AQ5: Mining and construction | AR5: 257.05031 | AS5: 59.046419 | AT5: 427.09417 | AU5: 12308.171
A6: 3 | B6: Food processing | C6: 4.3708782 | D6: 0 | E6: 27.438855 | F6: 24.832201 | G6: 3.0287217 | H6: 1.0627357 | I6: 0 | J6: 0.82190002 | K6: 0.50738059 | L6: 0 | M6: 0 | N6: 1.6301475 | O6: 0.0029201458 | P6: 0.010817811 | Q6: 22.772451 | R6: 0.071392393 | S6: 5.305507 | T6: 259.58437 | U6: 0.70259694 | V6: 1.4676277 | W6: 353.6105 | X6: 275.96967 | Y6: 36.758369 | Z6: 0.53506616 | AA6: 15.711225 | AB6: 4.4242067 | AC6: 0.39464466 | AD6: 342.50937 | AE6: 1029.913 | AJ6: 3 | AK6: Food processing | AL6: 275.96967 | AM6: 36.758369 | AN6: 0.53506616 | AO6: 15.711225 | AP6: 3 | AQ6: Food processing | AR6: 4.4242067 | AS6: 0.39464466 | AT6: 342.50937 | AU6: 1029.913
A7: 4 | B7: Other manufacturing | C7: 7.4967961 | D7: 20.774563 | E7: 8.9835575 | F7: 20.973669 | G7: 98.893814 | H7: 1.3948075 | I7: 513.74 | J7: 4.2345059 | K7: 7.8481971 | L7: 1.414324 | M7: 20.829774 | N7: 1.9516189 | O7: 5.0037656 | P7: 0.095572639 | Q7: 9.3288646 | R7: 0.12656071 | S7: 10.343583 | T7: 87.603401 | U7: 2.0696456 | V7: 2.3915376 | W7: 825.49855 | X7: 1798.3226 | Y7: 72.597517 | Z7: 105.68068 | AA7: 179.49326 | AB7: 47.446274 | AC7: 24.072004 | AD7: 1459.148 | AE7: 4512.2589 | AJ7: 4 | AK7: Other manufacturing | AL7: 1798.3226 | AM7: 72.597517 | AN7: 105.68068 | AO7: 179.49326 | AP7: 4 | AQ7: Other manufacturing | AR7: 47.446274 | AS7: 24.072004 | AT7: 1459.148 | AU7: 4512.2589
A8: 5 | B8: Transportation | C8: 53.911191 | D8: 362.12859 | E8: 17.180109 | F8: 70.634936 | G8: 581.36862 | H8: 125.60717 | I8: 54.449368 | J8: 71.714158 | K8: 90.497305 | L8: 181.87301 | M8: 162.57579 | N8: 454.70419 | O8: 98.350018 | P8: 8.1564658 | Q8: 108.88689 | R8: 3.8672828 | S8: 283.90956 | T8: 133.67704 | U8: 47.511922 | V8: 85.595272 | W8: 2996.5989 | X8: 1589.5328 | Y8: 3642.1391 | Z8: 111.5734 | AA8: 167.88014 | AB8: 13.907621 | AC8: 3.1354941 | AD8: 520.42623 | AE8: 9045.1937 | AJ8: 5 | AK8: Transportation | AL8: 1589.5328 | AM8: 3642.1391 | AN8: 111.5734 | AO8: 167.88014 | AP8: 5 | AQ8: Transportation | AR8: 13.907621 | AS8: 3.1354941 | AT8: 520.42623 | AU8: 9045.1937
A9: 6 | B9: Information | C9: 0.98339213 | D9: 43.615479 | E9: 2.8162012 | F9: 8.5756775 | G9: 50.93285 | H9: 449.09496 | I9: 8.1163314 | J9: 67.718149 | K9: 71.477046 | L9: 175.92555 | M9: 74.362148 | N9: 143.17539 | O9: 49.405184 | P9: 6.0692347 | Q9: 71.869135 | R9: 2.1582134 | S9: 124.40424 | T9: 52.309184 | U9: 17.723432 | V9: 9.0368944 | W9: 1429.7687 | X9: 3485.7621 | Y9: 30.842144 | Z9: 0 | AA9: 171.39925 | AB9: 5.745789 | AC9: 19.8349 | AD9: 415.74633 | AE9: 5559.0992 | AJ9: 6 | AK9: Information | AL9: 3485.7621 | AM9: 30.842144 | AN9: 0 | AO9: 171.39925 | AP9: 6 | AQ9: Information | AR9: 5.745789 | AS9: 19.8349 | AT9: 415.74633 | AU9: 5559.0992
A10: 7 | B10: Utilities | C10: 12.230099 | D10: 137.49532 | E10: 18.895984 | F10: 45.133059 | G10: 30.1384 | H10: 36.64114 | I10: 303.72487 | J10: 31.250758 | K10: 137.62896 | L10: 36.92514 | M10: 112.3379 | N10: 71.461217 | O10: 51.629255 | P10: 2.7470571 | Q10: 161.37213 | R10: 5.8794071 | S10: 595.69603 | T10: 212.80447 | U10: 42.821015 | V10: 24.465696 | W10: 2071.2779 | X10: 1543.4139 | Y10: 0 | Z10: 0 | AA10: 636.26452 | AB10: 54.717269 | AC10: 48.663152 | AD10: 0 | AE10: 4354.3367 | AJ10: 7 | AK10: Utilities | AL10: 1543.4139 | AM10: 0 | AN10: 0 | AO10: 636.26452 | AP10: 7 | AQ10: Utilities | AR10: 54.717269 | AS10: 48.663152 | AT10: 0 | AU10: 4354.3367
A11: 8 | B11: Wholesale trade | C11: 24.52737 | D11: 496.26597 | E11: 35.081087 | F11: 58.252802 | G11: 94.54923 | H11: 50.062792 | I11: 27.587809 | J11: 68.428252 | K11: 21.790383 | L11: 7.3204853 | M11: 66.172243 | N11: 47.02989 | O11: 24.088693 | P11: 1.4367261 | Q11: 83.875636 | R11: 0.98828382 | S11: 121.12284 | T11: 208.25324 | U11: 13.336463 | V11: 16.216654 | W11: 1466.3869 | X11: 2459.0685 | Y11: 143.48286 | Z11: 486.25996 | AA11: 171.28634 | AB11: 0.34133486 | AC11: 0.036286071 | AD11: 199.95326 | AE11: 4926.8154 | AJ11: 8 | AK11: Wholesale trade | AL11: 2459.0685 | AM11: 143.48286 | AN11: 486.25996 | AO11: 171.28634 | AP11: 8 | AQ11: Wholesale trade | AR11: 0.34133486 | AS11: 0.036286071 | AT11: 199.95326 | AU11: 4926.8154
A12: 9 | B12: Retail trade | C12: 8.7130548 | D12: 707.77608 | E12: 12.039079 | F12: 17.691162 | G12: 10.809896 | H12: 69.814171 | I12: 17.367992 | J12: 36.935054 | K12: 86.615794 | L12: 15.448418 | M12: 220.07195 | N12: 111.47197 | O12: 48.670121 | P12: 0.25309715 | Q12: 46.514654 | R12: 0.27912927 | S12: 39.38872 | T12: 30.421818 | U12: 19.228102 | V12: 0.2128516 | W12: 1499.7231 | X12: 5115.584 | Y12: 3233.178 | Z12: 726.59616 | AA12: 142.99067 | AB12: 0.45655125 | AC12: 0.12309747 | AD12: 113.4179 | AE12: 10832.07 | AJ12: 9 | AK12: Retail trade | AL12: 5115.584 | AM12: 3233.178 | AN12: 726.59616 | AO12: 142.99067 | AP12: 9 | AQ12: Retail trade | AR12: 0.45655125 | AS12: 0.12309747 | AT12: 113.4179 | AU12: 10832.07
A13: 10 | B13: Finance and insurance | C13: 11.099208 | D13: 182.29036 | E13: 3.0524608 | F13: 19.348632 | G13: 67.335701 | H13: 101.14327 | I13: 53.350782 | J13: 52.973277 | K13: 121.46094 | L13: 1146.0864 | M13: 961.25804 | N13: 86.287022 | O13: 35.787745 | P13: 1.9272309 | Q13: 60.155501 | R13: 1.5212643 | S13: 344.63984 | T13: 82.582708 | U13: 14.113078 | V13: 7.3505428 | W13: 3353.764 | X13: 3338.8214 | Y13: 0 | Z13: 0 | AA13: 101.64011 | AB13: 0 | AC13: 0 | AD13: 1688.0817 | AE13: 8482.3072 | AJ13: 10 | AK13: Finance and insurance | AL13: 3338.8214 | AM13: 0 | AN13: 0 | AO13: 101.64011 | AP13: 10 | AQ13: Finance and insurance | AR13: 0 | AS13: 0 | AT13: 1688.0817 | AU13: 8482.3072
A14: 11 | B14: Real estate and rentals | C14: 29.668688 | D14: 699.27124 | E14: 26.134044 | F14: 46.213244 | G14: 173.68068 | H14: 296.39715 | I14: 37.137107 | J14: 169.87535 | K14: 691.569 | L14: 307.73954 | M14: 771.01471 | N14: 537.70623 | O14: 191.41313 | P14: 24.370788 | Q14: 467.42248 | R14: 8.8139667 | S14: 481.74084 | T14: 331.33799 | U14: 100.58954 | V14: 16.154188 | W14: 5408.2499 | X14: 16202.579 | Y14: 1957.0938 | Z14: 54.714113 | AA14: 242.28443 | AB14: 0.20752292 | AC14: 0.33134275 | AD14: 379.02298 | AE14: 24244.483 | AJ14: 11 | AK14: Real estate and rentals | AL14: 16202.579 | AM14: 1957.0938 | AN14: 54.714113 | AO14: 242.28443 | AP14: 11 | AQ14: Real estate and rentals | AR14: 0.20752292 | AS14: 0.33134275 | AT14: 379.02298 | AU14: 24244.483
A15: 12 | B15: Professional services | C15: 3.9879062 | D15: 848.07211 | E15: 10.23357 | F15: 30.135478 | G15: 154.31984 | H15: 191.44433 | I15: 138.69962 | J15: 82.02277 | K15: 130.21881 | L15: 347.17325 | M15: 260.78763 | N15: 604.34729 | O15: 273.71703 | P15: 5.9556827 | Q15: 328.02316 | R15: 8.165405 | S15: 436.60857 | T15: 242.60098 | U15: 44.561439 | V15: 23.64554 | W15: 4164.7204 | X15: 1764.2235 | Y15: 158.14713 | Z15: 815.63969 | AA15: 33.685874 | AB15: 350.6145 | AC15: 168.3544 | AD15: 1079.9904 | AE15: 8535.3759 | AJ15: 12 | AK15: Professional services | AL15: 1764.2235 | AM15: 158.14713 | AN15: 815.63969 | AO15: 33.685874 | AP15: 12 | AQ15: Professional services | AR15: 350.6145 | AS15: 168.3544 | AT15: 1079.9904 | AU15: 8535.3759
... A23: 20 | B23: Government | C23: 8.3074115 | D23: 37.436161 | E23: 10.770889 | F23: 30.388824 | G23: 622.01844 | H23: 53.160852 | I23: 54.505234 | J23: 44.661783 | K23: 207.7458 | L23: 139.95696 | M23: 258.77789 | N23: 81.258502 | O23: 98.158733 | P23: 2.2317168 | Q23: 178.1453 | R23: 7.5922018 | S23: 344.04406 | T23: 101.33963 | U23: 18.556315 | V23: 23.265176 | W23: 2322.3219 | X23: 5715.0026 | Y23: 178.31765 | Z23: 0 | AA23: 2410.852 | AB23: 8174.3487 | AC23: 1542.1621 | AD23: 0 | AE23: 20343.005 | AJ23: 20 | AK23: Government | AL23: 5715.0026 | AM23: 178.31765 | AN23: 0 | AO23: 2410.852 | AP23: 20 | AQ23: Government | AR23: 8174.3487 | AS23: 1542.1621 | AT23: 0 | AU23: 20343.005
B24: Total intermediate input | C24: 280.24885 | D24: 4380.4955 | E24: 434.43689 | F24: 559.65211 | G24: 2760.4435 | H24: 1895.6029 | I24: 1726.2226 | J24: 1075.393 | K24: 2207.955 | L24: 3449.9742 | M24: 5526.6433 | N24: 3171.837 | O24: 1259.6528 | P24: 103.56224 | Q24: 3461.5436 | R24: 72.053901 | S24: 5035.9565 | T24: 2698.0238 | U24: 506.72951 | V24: 357.1529 | W24: 40963.58 | X24: 62731.926 | Y24: 21195.175 | Z24: 8591.5382 | AA24: 6889.6194 | AB24: 9012.1278 | AC24: 1975.8191 | AD24: 7258.2872 | AE24: 158618.07 | AK24: Total Hawaii produced | AL24: 62731.926 | AM24: 21195.175 | AN24: 8591.5382 | AO24: 6889.6194 | AQ24: Total Hawaii produced | AR24: 9012.1278 | AS24: 1975.8191 | AT24: 7258.2872 | AU24: 158618.07
B25: Imports | C25: 147.52845 | D25: 2050.3752 | E25: 201.35918 | F25: 2551.2235 | G25: 804.34997 | H25: 1210.6962 | I25: 252.51392 | J25: 512.22218 | K25: 796.8142 | L25: 855.43215 | M25: 652.33938 | N25: 727.73857 | O25: 201.36619 | P25: 12.083775 | Q25: 1123.2314 | R25: 16.450099 | S25: 882.31512 | T25: 1188.4896 | U25: 186.01182 | V25: 128.75176 | W25: 14501.293 | X25: 10288.719 | Y25: 1450.1507 | Z25: 8499.9481 | AA25: 7027.5095 | AB25: 371.60532 | AC25: 246.99989 | AD25: 964.74182 | AE25: 43350.967 | AK25: Imports | AL25: 10288.719 | AM25: 1450.1507 | AN25: 8499.9481 | AO25: 7027.5095 | AQ25: Imports | AR25: 371.60532 | AS25: 246.99989 | AT25: 964.74182 | AU25: 43350.967
B26: Earnings (Labor income) | C26: 374.218 | D26: 4651.438 | E26: 310.6 | F26: 670.35616 | G26: 2905.919 | H26: 910.069 | I26: 639.533 | J26: 1589.348 | K26: 3372.194 | L26: 1909.446 | M26: 2899.461 | N26: 3830.794 | O26: 3639.17 | P26: 478.43344 | Q26: 5120.3695 | R26: 903.39 | S26: 3022.717 | T26: 2882.863 | U26: 1399.1878 | V26: 17035.49 | W26: 58544.997 | AK26: Total | AL26: =+AL25+AL24 -> 73020.645 | AM26: =+AM25+AM24 -> 22645.325 | AN26: =+AN25+AN24 -> 17091.486 | AO26: =+AO25+AO24 -> 13917.129 | AQ26: Total | AR26: =+AR25+AR24 -> 9383.7331 | AS26: =+AS25+AS24 -> 2222.819 | AT26: =+AT25+AT24 -> 8223.029 | AU26: =+AU25+AU24 -> 201969.04
B27: Compensation of employees | C27: 284.54 | D27: 3828.329 | E27: 311.881 | F27: 570.925 | G27: 2611.33 | H27: 910.069 | I27: 624.974 | J27: 1521.088 | K27: 3199.156 | L27: 1853.487 | M27: 1012.706 | N27: 2912.536 | O27: 3258.058 | P27: 419.37744 | Q27: 4516.2635 | R27: 643.144 | S27: 2895.626 | T27: 2629.691 | U27: 901.61638 | V27: 17035.49 | W27: 51940.287 | AE27: 51940.287 | AK27: * Includes inventory variation
B28: Proprietor's income | C28: 89.678 | D28: 823.109 | E28: -1.281 | F28: 99.431162 | G28: 294.589 | H28: -5.3290705e-15 | I28: 14.559 | J28: 68.26 | K28: 173.038 | L28: 55.959 | M28: 1886.755 | N28: 918.258 | O28: 381.112 | P28: 59.056 | Q28: 604.106 | R28: 260.246 | S28: 127.091 | T28: 253.172 | U28: 497.57144 | V28: 0 | W28: 6604.7096 | AE28: 6604.7096
B29: TOPILS | C29: -2.747 | D29: 137.563 | E29: 28.675499 | F29: 50.596501 | G29: 1085.826 | H29: 104.204 | I29: 400.856 | J29: 773.513 | K29: 2836.754 | L29: 317.509 | M29: 2193.241 | N29: 264.646 | O29: 161.849 | P29: 64.462 | Q29: 233.106 | R29: 123.13 | S29: 1371.686 | T29: 200.227 | U29: 99.500418 | V29: -270.598 | W29: 10173.999 | AE29: 10173.999
B30: Other capital costs | C30: 207.929 | D30: 1088.299 | E30: 54.841429 | F30: 680.43041 | G30: 1488.655 | H30: 1438.527 | I30: 1335.211 | J30: 976.339 | K30: 1618.352 | L30: 1949.945 | M30: 12972.798 | N30: 540.36 | O30: 543.581 | P30: 560.40456 | Q30: 2179.6245 | R30: 270.68 | S30: 1863.197 | T30: 562.11 | U30: 1010.7118 | V30: 3092.208 | W30: 34434.204 | AE30: 34434.204
B31: Total Value added | C31: 579.4 | D31: 5877.3 | E31: 394.11693 | F31: 1401.3831 | G31: 5480.4 | H31: 2452.8 | I31: 2375.6 | J31: 3339.2 | K31: 7827.3 | L31: 4176.9 | M31: 18065.5 | N31: 4635.8 | O31: 4344.6 | P31: 1103.3 | Q31: 7533.1 | R31: 1297.2 | S31: 6257.6 | T31: 3645.2 | U31: 2509.4 | V31: 19857.1 | W31: 103153.2 | AE31: 103153.2
B32: Output | C32: 1007.1773 | D32: 12308.171 | E32: 1029.913 | F32: 4512.2587 | G32: 9045.1934 | H32: 5559.0991 | I32: 4354.3365 | J32: 4926.8152 | K32: 10832.069 | L32: 8482.3063 | M32: 24244.483 | N32: 8535.3755 | O32: 5805.619 | P32: 1218.946 | Q32: 12117.875 | R32: 1385.704 | S32: 12175.872 | T32: 7531.7134 | U32: 3202.1413 | V32: 20343.005 | W32: 158618.07 | X32: 73020.645 | Y32: 22645.325 | Z32: 17091.486 | AA32: 13917.129 | AB32: 9383.7331 | AC32: 2222.819 | AD32: 8223.029 | AE32: 305122.24
B33: Wage and salary jobs | C33: 7332 | D33: 37982 | E33: 5862 | F33: 6667 | G33: 29582 | H33: 8510 | I33: 3616 | J33: 17333 | K33: 64327 | L33: 16344 | M33: 12487 | N33: 26204 | O33: 45751 | P33: 16135 | Q33: 73339 | R33: 12045 | S33: 37127 | T33: 63783 | U33: 27053 | V33: 172482 | W33: 683961 | AE33: 683961
B34: Proprietors' jobs | C34: 8352 | D34: 11985 | E34: 616 | F34: 3117 | G34: 14783 | H34: 2509 | I34: 437 | J34: 4356 | K34: 19981 | L34: 19438 | M34: 40604 | N34: 23686 | O34: 15509 | P34: 4339 | Q34: 12615 | R34: 9803 | S34: 1392 | T34: 4072 | U34: 34199.561 | V34: 0 | W34: 231793.56 | AE34: 231793.56
B35: Total jobs | C35: 15684 | D35: 49967 | E35: 6478 | F35: 9784 | G35: 44365 | H35: 11019 | I35: 4053 | J35: 21689 | K35: 84308 | L35: 35782 | M35: 53091 | N35: 49890 | O35: 61260 | P35: 20474 | Q35: 85954 | R35: 21848 | S35: 38519 | T35: 67855 | U35: 61252.561 | V35: 172482 | W35: 915754.56 | AE35: 915754.56
B36: Earnings (RIMS II) | C36: 322.31265 | D36: 4042.1209 | E36: 235.61937 | F36: 537.44962 | G36: 2354.1371 | H36: 704.89283 | I36: 452.66359 | J36: 1348.9181 | K36: 2821.9954 | L36: 1622.874 | M36: 2758.4316 | N36: 3430.4979 | O36: 3125.5195 | P36: 421.58912 | Q36: 4309.6635 | R36: 801.63314 | S36: 2755.5666 | T36: 2617.4861 | U36: 1129.9397 | V36: 12095.127 | W36: 47888.437
B37: State total taxes | C37: 30.426382 | D37: 779.03474 | E37: 28.702418 | F37: 78.868972 | G37: 343.61457 | H37: 196.84883 | I37: 237.56231 | J37: 253.97659 | K37: 2002.0327 | L37: 483.63683 | M37: 1048.8383 | N37: 497.73061 | O37: 401.85201 | P37: 72.793292 | Q37: 662.84237 | R37: 88.91374 | S37: 1299.1189 | T37: 384.52473 | U37: 134.76844 | V37: 1253.4173 | W37: 10279.504 | AE37: 10279.504
B38: State individual income tax | C38: 17.113358 | D38: 269.73927 | E38: 18.600401 | F38: 43.185848 | G38: 174.79544 | H38: 53.022873 | I38: 35.516795 | J38: 98.767962 | K38: 186.75572 | L38: 123.65446 | M38: 175.46481 | N38: 237.53025 | O38: 224.53202 | P38: 33.673401 | Q38: 313.49485 | R38: 48.579977 | S38: 150.82839 | T38: 162.46685 | U38: 70.839871 | V38: 1058.6444 | W38: 3497.207 | AE38: 3497.207
B39: State GET | C39: 5.7616511 | D39: 413.5053 | E39: 2.8484791 | F39: 4.1863203 | G39: 78.807004 | H39: 48.572461 | I39: 0 | J39: 117.902 | K39: 1732.276 | L39: 3.1601065 | M39: 631.665 | N39: 188.98554 | O39: 127.89631 | P39: 27.51547 | Q39: 248.37217 | R39: 29.21132 | S39: 252.05102 | T39: 163.68294 | U39: 40.592896 | V39: 0 | W39: 4116.992 | AE39: 4116.992
B40: State TAT | C40: 0 | D40: 0 | E40: 0 | F40: 0 | G40: 0 | H40: 0 | I40: 0 | J40: 0 | K40: 0 | L40: 0 | M40: 0 | N40: 0 | O40: 0 | P40: 0 | Q40: 0 | R40: 0 | S40: 810.038 | T40: 0 | U40: 0 | V40: 0 | W40: 810.038 | AE40: 810.038
B41: State other taxes | C41: 7.5513729 | D41: 95.790172 | E41: 7.2535377 | F41: 31.496803 | G41: 90.012127 | H41: 95.253497 | I41: 202.04551 | J41: 37.306631 | K41: 83.001025 | L41: 356.82227 | M41: 241.70844 | N41: 71.214807 | O41: 49.423683 | P41: 11.604421 | Q41: 100.97534 | R41: 11.122444 | S41: 86.201462 | T41: 58.374931 | U41: 23.335677 | V41: 194.77285 | W41: 1855.267 | AE41: 1855.267
A43: Note. TOPILS = Taxes on production and imports less subsidies.

Sheet output earning ML
A1: 2022 Condensed Output, Earnings, State Tax, and Employment Multipliers for Hawaii
C3: Final-demand multipliers for state tax | T3: Direct-effect multipliers | AA3: Final-demand multipliers for state tax | AR3: Direct-effect multipliers
C4: Output multipliers | F4: Earnings multipliers | I4: State total tax multipliers | K4: State individual income tax multipliers | M4: State GET multipliers | O4: State TAT multipliers | Q4: State Other Taxes multipliers | T4: Earnings/earnings multipliers | X4: Output share | AA4: Output multipliers | AD4: Earnings multipliers | AG4: State total tax multipliers | AI4: State individual income tax multipliers | AK4: State GET multipliers | AM4: State TAT multipliers | AO4: State Other Taxes multipliers | AR4: Earnings/earnings multipliers
B5: Industry | C5: Type 1 | D5: Type 2 | F5: Type 1 | G5: Type 2 | I5: Type 1 | J5: Type 2 | K5: type 1 | L5: type 2 | M5: type 1 | N5: type 2 | O5: type 1 | P5: type 2 | Q5: type 1 | R5: type 2 | T5: Type 1 | U5: Type 2 | Z5: Industry | AA5: Type 1 | AB5: Type 2 | AD5: Type 1 | AE5: Type 2 | AG5: Type 1 | AH5: Type 2 | AI5: type 1 | AJ5: type 2 | AK5: type 1 | AL5: type 2 | AM5: type 1 | AN5: type 2 | AO5: type 1 | AP5: type 2 | AR5: Type 1 | AS5: Type 2
A6: 1 | B6: Agriculture | C6: 1.3860269 | D6: 1.9184367 | F6: 0.42911371 | G6: 0.57563331 | I6: 0.05004501 | J6: 0.082440279 | K6: 0.024405818 | L6: 0.035007647 | M6: 0.012821951 | N6: 0.026851971 | O6: 0.00076665015 | P6: 0.0019393378 | Q6: 0.012050591 | R6: 0.018641322 | T6: 1.3409141 | U6: 1.7987653 | X6: ='I-O condensed 2022'!AE4/'I-O condensed 2022'!AE$24 -> 0.0063497008 | Y6: 1 | Z6: Agriculture | AA6: =C6*$X6 -> 0.0088008561 | AB6: =D6*$X6 -> 0.012181499 | AD6: =F6*$X6 -> 0.0027247437 | AE6: =G6*$X6 -> 0.0036550993 | AG6: =I6*$X6 -> 0.00031777084 | AH6: =J6*$X6 -> 0.0005234711 | AI6: =K6*$X6 -> 0.00015496964 | AJ6: =L6*$X6 -> 0.00022228808 | AK6: =M6*$X6 -> 8.1415553e-05 | AL6: =N6*$X6 -> 0.00017050198 | AM6: =O6*$X6 -> 4.8679991e-06 | AN6: =P6*$X6 -> 1.2314215e-05 | ... AP6: =R6*$X6 -> 0.00011836682 | AR6: =T6*$X6 -> 0.0085144036 | AS6: =U6*$X6 -> 0.011421621
A7: 2 | B7: Mining and construction | C7: 1.4996401 | D7: 2.0834014 | F7: 0.47050218 | G7: 0.63115374 | I7: 0.099261627 | J7: 0.13478145 | K7: 0.03178984 | L7: 0.043414226 | M7: 0.051484777 | N7: 0.066868008 | O7: 0.0023453484 | P7: 0.003631143 | Q7: 0.013641661 | R7: 0.020868075 | T7: 1.4326689 | U7: 1.9218495 | X7: ='I-O condensed 2022'!AE5/'I-O condensed 2022'!AE$24 -> 0.077596269 | Y7: 2 | Z7: Mining and construction | AA7: =C7*$X7 -> 0.11636647 | AB7: =D7*$X7 -> 0.16166417 | AD7: =F7*$X7 -> 0.036509213 | AE7: =G7*$X7 -> 0.048975176 | AG7: =I7*$X7 -> 0.0077023319 | AH7: =J7*$X7 -> 0.010458538 | AI7: =K7*$X7 -> 0.002466773 | AJ7: =L7*$X7 -> 0.003368782 | AK7: =M7*$X7 -> 0.0039950267 | AL7: =N7*$X7 -> 0.0051887079 | AM7: =O7*$X7 -> 0.00018199029 | AN7: =P7*$X7 -> 0.00028176315 | ... AP7: =R7*$X7 -> 0.0016192848 | AR7: =T7*$X7 -> 0.11116976 | AS7: =U7*$X7 -> 0.14912835
A8: 3 | B8: Food processing | C8: 1.5914282 | D8: 2.1069548 | F8: 0.41550608 | G8: 0.55737939 | I8: 0.062244214 | J8: 0.093612195 | K8: 0.030735167 | L8: 0.041000801 | M8: 0.014310345 | N8: 0.027895459 | O8: 0.0037868702 | P8: 0.0049223708 | Q8: 0.013411832 | R8: 0.019793565 | T8: 1.8162137 | U8: 2.4363544 | X8: ='I-O condensed 2022'!AE6/'I-O condensed 2022'!AE$24 -> 0.0064930369 | Y8: 3 | Z8: Food processing | AA8: =C8*$X8 -> 0.010333202 | AB8: =D8*$X8 -> 0.013680535 | AD8: =F8*$X8 -> 0.0026978963 | AE8: =G8*$X8 -> 0.003619085 | AG8: =I8*$X8 -> 0.00040415398 | AH8: =J8*$X8 -> 0.00060782744 | AI8: =K8*$X8 -> 0.00019956457 | AJ8: =L8*$X8 -> 0.00026621971 | AK8: =M8*$X8 -> 9.2917597e-05 | AL8: =N8*$X8 -> 0.00018112625 | AM8: =O8*$X8 -> 2.4588288e-05 | AN8: =P8*$X8 -> 3.1961135e-05 | ... AP8: =R8*$X8 -> 0.00012852035 | AR8: =T8*$X8 -> 0.011792742 | AS8: =U8*$X8 -> 0.015819339
A9: 4 | B9: Other manufacturing | C9: 1.1730835 | D9: 1.3840419 | F9: 0.17002905 | G9: 0.22808496 | I9: 0.027846655 | J9: 0.040682732 | K9: 0.013211267 | L9: 0.017412063 | M9: 0.0042672338 | N9: 0.0098263921 | O9: 0.0011574901 | P9: 0.0016221477 | Q9: 0.0092106634 | R9: 0.011822129 | T9: 1.4275106 | U9: 1.9149299 | X9: ='I-O condensed 2022'!AE7/'I-O condensed 2022'!AE$24 -> 0.028447319 | Y9: 4 | Z9: Other manufacturing | AA9: =C9*$X9 -> 0.033371081 | AB9: =D9*$X9 -> 0.039372281 | AD9: =F9*$X9 -> 0.0048368706 | AE9: =G9*$X9 -> 0.0064884057 | AG9: =I9*$X9 -> 0.00079216267 | AH9: =J9*$X9 -> 0.0011573147 | AI9: =K9*$X9 -> 0.00037582514 | AJ9: =L9*$X9 -> 0.0004953265 | AK9: =M9*$X9 -> 0.00012139136 | AL9: =N9*$X9 -> 0.00027953451 | AM9: =O9*$X9 -> 3.2927489e-05 | AN9: =P9*$X9 -> 4.6145754e-05 | ... AP9: =R9*$X9 -> 0.00033630789 | AR9: =T9*$X9 -> 0.040608851 | AS9: =U9*$X9 -> 0.054474622
A10: 5 | B10: Transportation | C10: 1.4017991 | D10: 1.9041705 | F10: 0.40490322 | G10: 0.54315622 | I10: 0.060287731 | J10: 0.090855266 | K10: 0.030250789 | L10: 0.040254465 | M10: 0.01488792 | N10: 0.028126371 | O10: 0.00085252143 | P10: 0.0019590464 | Q10: 0.0142965 | R10: 0.020515384 | T10: 1.5557411 | U10: 2.0869443 | X10: ='I-O condensed 2022'!AE8/'I-O condensed 2022'!AE$24 -> 0.057024988 | Y10: 5 | Z10: Transportation | AA10: =C10*$X10 -> 0.079937579 | AB10: =D10*$X10 -> 0.1085853 | AD10: =F10*$X10 -> 0.023089601 | AE10: =G10*$X10 -> 0.030973477 | AG10: =I10*$X10 -> 0.0034379071 | AH10: =J10*$X10 -> 0.0051810205 | AI10: =K10*$X10 -> 0.0017250509 | AJ10: =L10*$X10 -> 0.0022955104 | AK10: =M10*$X10 -> 0.00084898348 | AL10: =N10*$X10 -> 0.0016039059 | AM10: =O10*$X10 -> 4.8615024e-05 | AN10: =P10*$X10 -> 0.0001117146 | ... AP10: =R10*$X10 -> 0.0011698896 | AR10: =T10*$X10 -> 0.08871612 | AS10: =U10*$X10 -> 0.11900797
A11: 6 | B11: Information | C11: 1.4843882 | D11: 1.8021667 | F11: 0.25612433 | G11: 0.34357722 | I11: 0.063269865 | J11: 0.082605571 | K11: 0.018651317 | L11: 0.024979212 | M11: 0.018991182 | N11: 0.027365255 | O11: 0.0020555492 | P11: 0.0027554892 | Q11: 0.023571816 | R11: 0.027505614 | T11: 2.0199107 | U11: 2.7096031 | X11: ='I-O condensed 2022'!AE9/'I-O condensed 2022'!AE$24 -> 0.035047073 | Y11: 6 | Z11: Information | AA11: =C11*$X11 -> 0.052023462 | AB11: =D11*$X11 -> 0.063160669 | AD11: =F11*$X11 -> 0.0089764083 | AE11: =G11*$X11 -> 0.012041376 | AG11: =I11*$X11 -> 0.0022174236 | AH11: =J11*$X11 -> 0.0028950835 | AI11: =K11*$X11 -> 0.00065367408 | AJ11: =L11*$X11 -> 0.00087544827 | AK11: =M11*$X11 -> 0.00066558535 | AL11: =N11*$X11 -> 0.00095907211 | AM11: =O11*$X11 -> 7.2040984e-05 | AN11: =P11*$X11 -> 9.6571833e-05 | ... AP11: =R11*$X11 -> 0.00096399129 | AR11: =T11*$X11 -> 0.070791957 | AS11: =U11*$X11 -> 0.09496366
A12: 7 | B12: Utilities | C12: 1.5432311 | D12: 1.8389501 | F12: 0.23834476 | G12: 0.31972686 | I12: 0.082838687 | J12: 0.10083215 | K12: 0.017853797 | L12: 0.023742424 | M12: 0.0081241591 | N12: 0.015916923 | O12: 0.0022493674 | P12: 0.0029007192 | Q12: 0.054611363 | R12: 0.058272086 | T12: 2.2927253 | U12: 3.0755695 | X12: ='I-O condensed 2022'!AE10/'I-O condensed 2022'!AE$24 -> 0.027451706 | Y12: 7 | Z12: Utilities | AA12: =C12*$X12 -> 0.042364326 | AB12: =D12*$X12 -> 0.050482318 | AD12: =F12*$X12 -> 0.0065429702 | AE12: =G12*$X12 -> 0.0087770479 | AG12: =I12*$X12 -> 0.0022740633 | AH12: =J12*$X12 -> 0.0027680146 | AI12: =K12*$X12 -> 0.0004901172 | AJ12: =L12*$X12 -> 0.00065177004 | AK12: =M12*$X12 -> 0.00022302203 | AL12: =N12*$X12 -> 0.00043694669 | AM12: =O12*$X12 -> 6.1748974e-05 | AN12: =P12*$X12 -> 7.962969e-05 | ... AP12: =R12*$X12 -> 0.0015996682 | AR12: =T12*$X12 -> 0.062939222 | AS12: =U12*$X12 -> 0.084429632
A13: 8 | B13: Wholesale trade | C13: 1.3074157 | D13: 1.7602937 | F13: 0.36501233 | G13: 0.48964471 | I13: 0.071036437 | J13: 0.098592472 | K13: 0.026450489 | L13: 0.035468607 | M13: 0.030728356 | N13: 0.04266256 | O13: 0.0024955684 | P13: 0.003493079 | Q13: 0.011362023 | R13: 0.016968226 | T13: 1.3331783 | U13: 1.788388 | X13: ='I-O condensed 2022'!AE11/'I-O condensed 2022'!AE$24 -> 0.03106087 | Y13: 8 | Z13: Wholesale trade | AA13: =C13*$X13 -> 0.040609471 | AB13: =D13*$X13 -> 0.054676255 | AD13: =F13*$X13 -> 0.011337601 | AE13: =G13*$X13 -> 0.015208791 | AG13: =I13*$X13 -> 0.0022064535 | AH13: =J13*$X13 -> 0.003062368 | AI13: =K13*$X13 -> 0.00082157521 | AJ13: =L13*$X13 -> 0.0011016858 | AK13: =M13*$X13 -> 0.00095444948 | AL13: =N13*$X13 -> 0.0013251362 | AM13: =O13*$X13 -> 7.7514525e-05 | AN13: =P13*$X13 -> 0.00010849807 | ... AP13: =R13*$X13 -> 0.00052704786 | AR13: =T13*$X13 -> 0.041409677 | AS13: =U13*$X13 -> 0.055548888
A14: 9 | B14: Retail trade | C14: 1.2809017 | D14: 1.700364 | F14: 0.33807986 | G14: 0.45351622 | I14: 0.20216946 | J14: 0.22769227 | K14: 0.022790878 | L14: 0.031143593 | M14: 0.16619158 | N14: 0.17724522 | O14: 0.001712347 | P14: 0.0026362562 | Q14: 0.011474659 | R14: 0.016667207 | T14: 1.2977003 | U14: 1.7407962 | X14: ='I-O condensed 2022'!AE12/'I-O condensed 2022'!AE$24 -> 0.068290261 | Y14: 9 | Z14: Retail trade | AA14: =C14*$X14 -> 0.08747311 | AB14: =D14*$X14 -> 0.1161183 | AD14: =F14*$X14 -> 0.023087561 | AE14: =G14*$X14 -> 0.030970741 | AG14: =I14*$X14 -> 0.013806205 | AH14: =J14*$X14 -> 0.015549165 | AI14: =K14*$X14 -> 0.001556395 | AJ14: =L14*$X14 -> 0.0021268041 | AK14: =M14*$X14 -> 0.011349266 | AL14: =N14*$X14 -> 0.012104122 | AM14: =O14*$X14 -> 0.00011693663 | AN14: =P14*$X14 -> 0.00018003062 | ... AP14: =R14*$X14 -> 0.0011382079 | AR14: =T14*$X14 -> 0.088620293 | AS14: =U14*$X14 -> 0.11887943
A15: 10 | B15: Finance and insurance | C15: 1.6030345 | D15: 2.0471235 | F15: 0.35792856 | G15: 0.48014219 | I15: 0.093832814 | J15: 0.12085407 | K15: 0.026416294 | L15: 0.035259398 | M15: 0.0093029157 | N15: 0.021005513 | O15: 0.0046641631 | P15: 0.0056423151 | Q15: 0.053449441 | R15: 0.058946844 | T15: 1.870792 | U15: 2.5095683 | X15: ='I-O condensed 2022'!AE13/'I-O condensed 2022'!AE$24 -> 0.053476297 | Y15: 10 | Z15: Finance and insurance | AA15: =C15*$X15 -> 0.085724347 | AB15: =D15*$X15 -> 0.10947258 | AD15: =F15*$X15 -> 0.019140694 | AE15: =G15*$X15 -> 0.025676227 | AG15: =I15*$X15 -> 0.0050178314 | AH15: =J15*$X15 -> 0.0064628282 | AI15: =K15*$X15 -> 0.0014126456 | AJ15: =L15*$X15 -> 0.001885542 | AK15: =M15*$X15 -> 0.00049748548 | AL15: =N15*$X15 -> 0.0011232971 | AM15: =O15*$X15 -> 0.00024942217 | AN15: =P15*$X15 -> 0.00030173012 | ... AP15: =R15*$X15 -> 0.003152259 | AR15: =T15*$X15 -> 0.10004303 | AS15: =U15*$X15 -> 0.13420242
A16: 11 | B16: Real estate and rentals | C16: 1.3239566 | D16: 1.5808315 | F16: 0.207037 | G16: 0.27772917 | I16: 0.06370799 | J16: 0.079337925 | K16: 0.01375532 | L16: 0.018870446 | M16: 0.033628456 | N16: 0.040397602 | O16: 0.0015369184 | P16: 0.0021027119 | Q16: 0.014787297 | R16: 0.017967166 | T16: 1.8196953 | U16: 2.4410248 | X16: ='I-O condensed 2022'!AE14/'I-O condensed 2022'!AE$24 -> 0.15284818 | Y16: 11 | Z16: Real estate and rentals | AA16: =C16*$X16 -> 0.20236436 | AB16: =D16*$X16 -> 0.24162722 | AD16: =F16*$X16 -> 0.031645228 | AE16: =G16*$X16 -> 0.042450397 | AG16: =I16*$X16 -> 0.0097376502 | AH16: =J16*$X16 -> 0.012126657 | AI16: =K16*$X16 -> 0.0021024755 | AJ16: =L16*$X16 -> 0.0028843132 | AK16: =M16*$X16 -> 0.0051400481 | AL16: =N16*$X16 -> 0.0061746997 | AM16: =O16*$X16 -> 0.00023491517 | AN16: =P16*$X16 -> 0.00032139568 | ... AP16: =R16*$X16 -> 0.0027462485 | AR16: =T16*$X16 -> 0.27813711 | AS16: =U16*$X16 -> 0.3731062
A17: 12 | B17: Professional services | C17: 1.537953 | D17: 2.2240284 | F17: 0.55296568 | G17: 0.74177416 | I17: 0.092821424 | J17: 0.1345667 | K17: 0.038280822 | L17: 0.05194258 | M17: 0.034087659 | N17: 0.052167062 | O17: 0.0059048307 | P17: 0.0074159827 | Q17: 0.014548112 | R17: 0.023041078 | T17: 1.3758264 | U17: 1.8455983 | X17: ='I-O condensed 2022'!AE15/'I-O condensed 2022'!AE$24 -> 0.053810866 | Y17: 12 | Z17: Professional services | AA17: =C17*$X17 -> 0.082758584 | AB17: =D17*$X17 -> 0.1196769 | AD17: =F17*$X17 -> 0.029755562 | AE17: =G17*$X17 -> 0.03991551 | AG17: =I17*$X17 -> 0.0049948012 | AH17: =J17*$X17 -> 0.0072411509 | AI17: =K17*$X17 -> 0.0020599242 | AJ17: =L17*$X17 -> 0.0027950752 | AK17: =M17*$X17 -> 0.0018342865 | AL17: =N17*$X17 -> 0.0028071548 | AM17: =O17*$X17 -> 0.00031774406 | AN17: =P17*$X17 -> 0.00039906045 | ... AP17: =R17*$X17 -> 0.0012398604 | AR17: =T17*$X17 -> 0.074034413 | AS17: =U17*$X17 -> 0.099313243
... A25: 20 | B25: Government | C25: 1.024827 | D25: 1.7720302 | F25: 0.60223368 | G25: 0.80786457 | I25: 0.063039523 | J25: 0.10850421 | K25: 0.052591758 | L25: 0.067470748 | M25: 0.0004426528 | N25: 0.02013289 | O25: 0.00012541847 | P25: 0.0017712107 | Q25: 0.009879693 | R25: 0.019129364 | T25: 1.0129073 | U25: 1.3587615 | X25: ='I-O condensed 2022'!AE23/'I-O condensed 2022'!AE$24 -> 0.12825149 | Y25: 20 | Z25: Government | AA25: =C25*$X25 -> 0.13143559 | AB25: =D25*$X25 -> 0.22726552 | AD25: =F25*$X25 -> 0.07723737 | AE25: =G25*$X25 -> 0.10360984 | AG25: =I25*$X25 -> 0.008084913 | AH25: =J25*$X25 -> 0.013915827 | AI25: =K25*$X25 -> 0.0067449716 | AJ25: =L25*$X25 -> 0.0086532243 | AK25: =M25*$X25 -> 5.6770883e-05 | AL25: =N25*$X25 -> 0.0025820733 | AM25: =O25*$X25 -> 1.6085107e-05 | AN25: =P25*$X25 -> 0.00022716042 | ... AP25: =R25*$X25 -> 0.0024533695 | AR25: =T25*$X25 -> 0.12990688 | AS25: =U25*$X25 -> 0.1742632
B26: State average | C26: =AVERAGE(C6:C25) -> 1.3686801 | D26: =AVERAGE(D6:D25) -> 1.8789055 | F26: =AVERAGE(F6:F25) -> 0.41123339 | G26: =AVERAGE(G6:G25) -> 0.55164781 | I26: =AVERAGE(I6:I25) -> 0.080666784 | J26: =AVERAGE(J6:J25) -> 0.11171221 | K26: =AVERAGE(K6:K25) -> 0.028902138 | L26: =AVERAGE(L6:L25) -> 0.03906221 | M26: =AVERAGE(M6:M25) -> 0.029242936 | N26: =AVERAGE(N6:N25) -> 0.042688353 | O26: =AVERAGE(O6:O25) -> 0.0054449388 | P26: =AVERAGE(P6:P25) -> 0.0065687629 | ... R26: =AVERAGE(R6:R25) -> 0.02339288 | T26: =AVERAGE(T6:T25) -> 1.483739 | U26: =AVERAGE(U6:U25) -> 1.9903573 | Z26: State average | AA26: 1.3686801 | AB26: 1.8789055 | AD26: 0.41123339 | AE26: 0.55164781 | AG26: 0.080666784 | AH26: 0.11171221 | AI26: 0.028902138 | AJ26: 0.03906221 | AK26: 0.029242936 | AL26: 0.042688353 | AM26: 0.0054449388 | AN26: 0.0065687629 | AO26: 0.017076771 | AP26: 0.02339288 | AR26: 1.483739 | AS26: 1.9903573
B27: State weighted average 1/ | C27: 1.3645036 | D27: 1.8720002 | F27: 0.40903404 | G27: 0.54869749 | I27: 0.087263335 | J27: 0.11814272 | K27: 0.02964176 | L27: 0.039747494 | M27: 0.033770187 | N27: 0.047143695 | O27: 0.0072257009 | P27: 0.0083435145 | Q27: 0.016625687 | R27: 0.022908017 | T27: 1.5008793 | U27: 2.01335 | Z27: State weighted average 1/ | AA27: =SUM(AA6:AA25) -> 1.3645036 | AB27: =SUM(AB6:AB25) -> 1.8720002 | AD27: =SUM(AD6:AD25) -> 0.40903404 | AE27: =SUM(AE6:AE25) -> 0.54869749 | AG27: =SUM(AG6:AG25) -> 0.087263335 | AH27: =SUM(AH6:AH25) -> 0.11814272 | AI27: =SUM(AI6:AI25) -> 0.02964176 | AJ27: =SUM(AJ6:AJ25) -> 0.039747494 | AK27: =SUM(AK6:AK25) -> 0.033770187 | AL27: =SUM(AL6:AL25) -> 0.047143695 | AM27: =SUM(AM6:AM25) -> 0.0072257009 | AN27: =SUM(AN6:AN25) -> 0.0083435145 | ... AP27: =SUM(AP6:AP25) -> 0.022908017 | AR27: =SUM(AR6:AR25) -> 1.5008793 | AS27: =SUM(AS6:AS25) -> 2.01335
A28: 1/ Output as weight.

Sheet job ML
A1: 2022 Condensed Type I and II Employment Multipliers for Hawaii
C3: Direct-effect multipliers | I3: Final-demand multipliers | O3: Final-demand multipliers | U3: Final-demand multipliers | AA3: Final-demand multipliers | AG3: Final-demand multipliers | AM3: Final-demand multipliers | AS3: Final-demand multipliers | AY3: Final-demand multipliers | BE3: Final-demand multipliers | BK3: Final-demand multipliers | BQ3: Final-demand multipliers | BY3: Direct-effect multipliers | CE3: Final-demand multipliers
C4: W&s/w&s job multipliers | F4: Total job/total job multipliers | I4: W&s job multipliers | L4: Total job multipliers | O4: W&s job multipliers | R4: Total job multipliers | U4: W&s job multipliers | X4: Total job multipliers | AA4: W&s job multipliers | AD4: Total job multipliers | AG4: W&s job multipliers | AJ4: Total job multipliers | AM4: W&s job multipliers | AP4: Total job multipliers | AS4: W&s job multipliers | AV4: Total job multipliers | AY4: W&s job multipliers | BB4: Total job multipliers | BE4: W&s job multipliers | BH4: Total job multipliers | BK4: W&s job multipliers | BN4: Total job multipliers | BQ4: W&s job multipliers | BT4: Total job multipliers | BW4: Output share | BY4: W&s/w&s job multipliers | CB4: Total job/total job multipliers | CE4: W&s job multipliers | CH4: Total job multipliers
C5: 2022 | D5: 2022 | F5: 2022 | G5: 2022 | I5: 2022 | J5: 2022 | L5: 2022 | M5: 2022 | O5: 2023 | P5: 2023 | R5: 2023 | S5: 2023 | U5: 2024 | V5: 2024 | X5: 2024 | Y5: 2024 | AA5: 2025 | AB5: 2025 | AD5: 2025 | AE5: 2025 | AG5: 2026 | AH5: 2026 | AJ5: 2026 | AK5: 2026 | AM5: 2027 | AN5: 2027 | AP5: 2027 | AQ5: 2027 | AS5: 2028 | AT5: 2028 | AV5: 2028 | AW5: 2028 | AY5: 2029 | AZ5: 2029 | BB5: 2029 | BC5: 2029 | BE5: 2030 | BF5: 2030 | BH5: 2030 | BI5: 2030 | BK5: 2031 | BL5: 2031 | BN5: 2031 | BO5: 2031 | BQ5: 2032 | BR5: 2032 | BT5: 2032 | BU5: 2032 | BY5: 2022 | BZ5: 2022 | CB5: 2022 | CC5: 2022 | CE5: 2022 | CF5: 2022 | CH5: 2022 | CI5: 2022
B6: Industry | C6: Type1 | D6: Type 2 | F6: Type1 | G6: Type 2 | I6: Type1 | J6: Type 2 | L6: Type1 | M6: Type 2 | O6: Type1 | P6: Type 2 | R6: Type1 | S6: Type 2 | U6: Type1 | V6: Type 2 | X6: Type1 | Y6: Type 2 | AA6: Type1 | AB6: Type 2 | AD6: Type1 | AE6: Type 2 | AG6: Type1 | AH6: Type 2 | AJ6: Type1 | AK6: Type 2 | AM6: Type1 | AN6: Type 2 | AP6: Type1 | AQ6: Type 2 | AS6: Type1 | AT6: Type 2 | AV6: Type1 | AW6: Type 2 | AY6: Type1 | AZ6: Type 2 | BB6: Type1 | BC6: Type 2 | BE6: Type1 | BF6: Type 2 | BH6: Type1 | BI6: Type 2 | BK6: Type1 | BL6: Type 2 | BN6: Type1 | BO6: Type 2 | BQ6: Type1 | BR6: Type 2 | BT6: Type1 | BU6: Type 2 | BY6: Type1 | BZ6: Type 2 | CB6: Type1 | CC6: Type 2 | CE6: Type1 | CF6: Type 2 | CH6: Type1 | CI6: Type 2
A7: 1 | B7: Agriculture | C7: 1.2282026 | D7: 1.526608 | F7: 1.1762665 | G7: 1.3720988 | I7: 8.9410091 | J7: 11.113326 | L7: 18.317097 | M7: 21.366643 | O7: 8.596809 | P7: 10.707444 | R7: 17.602104 | S7: 20.576108 | U7: 8.2668915 | V7: 10.319167 | X7: 16.916557 | Y7: 19.819396 | AA7: 8.1121544 | AB7: 10.098005 | AD7: 16.61176 | AE7: 19.421309 | AG7: 7.9606307 | AH7: 9.8822914 | AJ7: 16.312888 | AK7: 19.032256 | AM7: 7.8122424 | AN7: 9.6718696 | AP7: 16.019809 | AQ7: 18.652 | AS7: 7.6669137 | AT7: 9.4665888 | AV7: 15.732396 | AW7: 18.280309 | AY7: 7.5245711 | AZ7: 9.2663031 | BB7: 15.450525 | BC7: 17.916959 | BE7: 7.385143 | BF7: 9.0708712 | BH7: 15.174074 | BI7: 17.561734 | BK7: 7.2485602 | BL7: 8.8801563 | BN7: 14.902927 | BO7: 17.214423 | BQ7: 7.2485602 | BR7: 8.6940263 | BT7: 14.636969 | BU7: 16.874822 | BW7: 0.0063497008 | BY7: =C7*$BW7 -> 0.007798719 | BZ7: =D7*$BW7 -> 0.009693504 | CB7: =F7*$BW7 -> 0.0074689405 | CC7: =G7*$BW7 -> 0.008712417 | CE7: =I7*$BW7 -> 0.056772732 | CF7: =J7*$BW7 -> 0.070566296 | CH7: =L7*$BW7 -> 0.11630808 | CI7: =M7*$BW7 -> 0.13567179
A8: 2 | B8: Mining and construction | C8: 1.6154535 | D8: 2.387295 | F8: 1.6783868 | G8: 2.5020217 | I8: 4.9851564 | J8: 7.3669957 | L8: 6.8136814 | M8: 10.15736 | O8: 4.8214193 | P8: 7.1356273 | R8: 6.5955606 | S8: 9.8564104 | U8: 4.6643638 | V8: 6.9145833 | X8: 6.3864688 | Y8: 9.5692896 | AA8: 4.5050944 | AB8: 6.6824825 | AD8: 6.1698987 | AE8: 9.250431 | AG8: 4.3513518 | AH8: 6.4583587 | AJ8: 5.9607883 | AK8: 8.9424423 | AM8: 4.202941 | AN8: 6.2419312 | AP8: 5.7588766 | AQ8: 8.6449448 | AS8: 4.0596739 | AT8: 6.0329296 | AV8: 5.5639117 | AW8: 8.3575732 | AY8: 3.9213691 | AZ8: 5.831093 | BB8: 5.3756508 | BC8: 8.0799753 | BE8: 3.7878517 | BF8: 5.6361701 | BH8: 5.1938595 | BI8: 7.8118114 | BK8: 3.6589532 | BL8: 5.4479185 | BN8: 5.0183121 | BO8: 7.5527539 | BQ8: 3.6589532 | BR8: 5.2661047 | BT8: 4.8487906 | BU8: 7.3024867 | BW8: 0.077596269 | BY8: =C8*$BW8 -> 0.12535317 | BZ8: =D8*$BW8 -> 0.18524519 | CB8: =F8*$BW8 -> 0.13023655 | CC8: =G8*$BW8 -> 0.19414755 | CE8: =I8*$BW8 -> 0.38682954 | CF8: =J8*$BW8 -> 0.57165138 | CH8: =L8*$BW8 -> 0.52871626 | CI8: =M8*$BW8 -> 0.78817322
A9: 3 | B9: Food processing | C9: 1.5286257 | D9: 1.898184 | F9: 1.7060511 | G9: 2.1755125 | I9: 8.7005444 | J9: 10.803975 | L9: 10.730809 | M9: 13.683651 | O9: 8.971464 | P9: 11.015169 | R9: 11.001015 | S9: 13.88071 | U9: 9.2663472 | V9: 11.253543 | X9: 11.299066 | Y9: 14.109853 | AA9: 9.0677155 | AB9: 10.990593 | AD9: 11.053806 | AE9: 13.774261 | AG9: 8.8740499 | AH9: 10.734773 | AJ9: 10.814751 | AK9: 13.447885 | AM9: 8.6852031 | AN9: 10.48586 | AP9: 10.581715 | AQ9: 13.130436 | AS9: 8.5010325 | AT9: 10.243638 | AV9: 10.354519 | AW9: 12.821635 | AY9: 8.3214007 | AZ9: 10.007901 | BB9: 10.132991 | BC9: 12.521212 | BE9: 8.1461747 | BF9: 9.7784467 | BH9: 9.9169632 | BI9: 12.228908 | BK9: 7.9752263 | BL9: 9.5550828 | BN9: 9.7062752 | BO9: 11.944471 | BQ9: 7.9752263 | BR9: 9.3376223 | BT9: 9.5007711 | BU9: 11.667659 | BW9: 0.0064930369 | BY9: =C9*$BW9 -> 0.009925423 | BZ9: =D9*$BW9 -> 0.012324979 | CB9: =F9*$BW9 -> 0.011077453 | CC9: =G9*$BW9 -> 0.014125683 | CE9: =I9*$BW9 -> 0.056492956 | CF9: =J9*$BW9 -> 0.070150609 | CH9: =L9*$BW9 -> 0.069675536 | CI9: =M9*$BW9 -> 0.088848449
A10: 4 | B10: Other manufacturing | C10: 1.496672 | D10: 2.0792278 | F10: 1.4593613 | G10: 2.0166285 | I10: 2.2113786 | J10: 3.0721225 | L10: 3.1643555 | M10: 4.3726866 | O10: 2.1711995 | P10: 3.0075029 | R10: 3.1082419 | S10: 4.2866407 | U10: 2.1325421 | V10: 2.9457215 | X10: 3.0541492 | Y10: 4.20435 | AA10: 2.0593011 | AB10: 2.8461609 | AD10: 2.9497325 | AE10: 4.0629685 | AG10: 1.9886279 | AH10: 2.7500534 | AJ10: 2.8489531 | AK10: 3.9264567 | AM10: 1.9204308 | AN10: 2.6572766 | AP10: 2.7516822 | AQ10: 3.7946433 | AS10: 1.8546214 | AT10: 2.5677123 | AV10: 2.6577959 | AW10: 3.6673631 | AY10: 1.7911148 | AZ10: 2.4812467 | BB10: 2.5671742 | BC10: 3.5444571 | BE10: 1.7298287 | BF10: 2.39777 | BH10: 2.479702 | BI10: 3.4257718 | BK10: 1.6706843 | BL10: 2.3171766 | BN10: 2.395268 | BO10: 3.311159 | BQ10: 1.6706843 | BR10: 2.2393646 | BT10: 2.3137649 | BU10: 3.2004763 | BW10: 0.028447319 | BY10: =C10*$BW10 -> 0.042576307 | BZ10: =D10*$BW10 -> 0.059148455 | CB10: =F10*$BW10 -> 0.041514915 | CC10: =G10*$BW10 -> 0.057367674 | CE10: =I10*$BW10 -> 0.062907793 | CF10: =J10*$BW10 -> 0.087393649 | CH10: =L10*$BW10 -> 0.09001743 | CI10: =M10*$BW10 -> 0.12439121
A11: 5 | B11: Transportation | C11: 1.6214406 | D11: 2.2481877 | F11: 1.5278355 | G11: 2.1145022 | I11: 5.3028667 | J11: 7.3526221 | L11: 7.4937503 | M11: 10.371242 | O11: 5.1475616 | P11: 7.1391151 | R11: 7.2719052 | S11: 10.078117 | U11: 4.9980872 | V11: 6.9345737 | X11: 7.0584009 | Y11: 9.7974623 | AA11: 4.8607274 | AB11: 6.734537 | AD11: 6.868362 | AE11: 9.5193964 | AG11: 4.7273473 | AH11: 6.5405884 | AJ11: 6.6837024 | AK11: 9.2496444 | AM11: 4.5978247 | AN11: 6.3525322 | AP11: 6.504261 | AQ11: 8.9879441 | AS11: 4.4720416 | AT11: 6.1701795 | AV11: 6.3298817 | AW11: 8.7340418 | AY11: 4.3498836 | AZ11: 5.9933475 | BB11: 6.1604137 | BC11: 8.4876925 | BE11: 4.2312401 | BF11: 5.8218599 | BH11: 5.9957106 | BI11: 8.248659 | BK11: 4.1160042 | BL11: 5.655546 | BN11: 5.8356308 | BO11: 8.0167124 | BQ11: 4.1160042 | BR11: 5.4942412 | BT11: 5.6800371 | BU11: 7.7916308 | BW11: 0.057024988 | BY11: =C11*$BW11 -> 0.092462628 | BZ11: =D11*$BW11 -> 0.12820288 | CB11: =F11*$BW11 -> 0.0871248 | CC11: =G11*$BW11 -> 0.12057946 | CE11: =I11*$BW11 -> 0.30239591 | CF11: =J11*$BW11 -> 0.41928319 | CH11: =L11*$BW11 -> 0.42733102 | CI11: =M11*$BW11 -> 0.59141995
A12: 6 | B12: Information | C12: 2.1725567 | D12: 3.0195433 | F12: 2.2888046 | G12: 3.2070863 | I12: 3.325801 | J12: 4.622388 | L12: 4.5367671 | M12: 6.3569443 | O12: 3.1386241 | P12: 4.398395 | R12: 4.2945291 | S12: 6.0696176 | U12: 2.9656344 | V12: 4.1905724 | X12: 4.0707677 | Y12: 5.80338 | AA12: 2.8524533 | AB12: 4.0377445 | AD12: 3.9175924 | AE12: 5.5945225 | AG12: 2.7437296 | AH12: 3.8907078 | AJ12: 3.7703751 | AK12: 5.3934794 | AM12: 2.6392834 | AN12: 3.7492358 | AP12: 3.6288782 | AQ12: 5.1999491 | AS12: 2.5389425 | AT12: 3.6131114 | AV12: 3.4928738 | AW12: 5.0136419 | AY12: 2.4425416 | AZ12: 3.4821261 | BB12: 3.3621431 | BC12: 4.8342794 | BE12: 2.3499222 | BF12: 3.3560798 | BH12: 3.2364764 | BI12: 4.6615946 | BK12: 2.2609322 | BL12: 3.2347801 | BN12: 3.1156723 | BO12: 4.4953306 | BQ12: 2.2609322 | BR12: 3.1180427 | BT12: 2.9995378 | BU12: 4.335241 | BW12: 0.035047073 | BY12: =C12*$BW12 -> 0.076141754 | BZ12: =D12*$BW12 -> 0.10582615 | CB12: =F12*$BW12 -> 0.080215902 | CC12: =G12*$BW12 -> 0.11239899 | CE12: =I12*$BW12 -> 0.11655959 | CF12: =J12*$BW12 -> 0.16200117 | CH12: =L12*$BW12 -> 0.15900041 | CI12: =M12*$BW12 -> 0.22279229
A13: 7 | B13: Utilities | C13: 3.1903394 | D13: 4.6432871 | F13: 3.6433214 | G13: 5.4630802 | I13: 2.6493743 | J13: 3.8559551 | L13: 3.3911899 | M13: 5.0850145 | O13: 2.5247363 | P13: 3.6970568 | R13: 3.2396995 | S13: 4.8915653 | U13: 2.4084606 | V13: 3.5483661 | X13: 3.0982876 | Y13: 4.7106258 | AA13: 2.3357789 | AB13: 3.4387898 | AD13: 3.0040872 | AE13: 4.5646086 | AG13: 2.2654369 | AH13: 3.3327945 | AJ13: 2.9129242 | AK13: 4.4233563 | AM13: 2.1973547 | AN13: 3.2302566 | AP13: 2.8246951 | AQ13: 4.2867058 | AS13: 2.1314549 | AT13: 3.1310573 | AV13: 2.7393001 | AW13: 4.1544999 | AY13: 2.0676631 | AZ13: 3.0350819 | BB13: 2.6566431 | BC13: 4.026587 | BE13: 2.0059075 | BF13: 2.9422199 | BH13: 2.5766312 | BI13: 3.9028208 | BK13: 1.9461191 | BL13: 2.8523646 | BN13: 2.4991749 | BO13: 3.7830604 | BQ13: 1.9461191 | BR13: 2.7654135 | BT13: 2.424188 | BU13: 3.6671697 | BW13: 0.027451706 | BY13: =C13*$BW13 -> 0.087580259 | BZ13: =D13*$BW13 -> 0.12746615 | CB13: =F13*$BW13 -> 0.10001539 | CC13: =G13*$BW13 -> 0.14997087 | CE13: =I13*$BW13 -> 0.072729845 | CF13: =J13*$BW13 -> 0.10585255 | CH13: =L13*$BW13 -> 0.093093948 | CI13: =M13*$BW13 -> 0.13959232
A14: 8 | B14: Wholesale trade | C14: 1.3579548 | D14: 1.8831864 | F14: 1.3948466 | G14: 1.9840932 | I14: 4.7774129 | J14: 6.6252274 | L14: 6.1404429 | M14: 8.7344454 | O14: 4.7146626 | P14: 6.5100092 | R14: 6.0623223 | S14: 8.5920671 | U14: 4.6539921 | V14: 6.3996968 | X14: 5.9868776 | Y14: 8.4560879 | AA14: 4.4499619 | AB14: 6.1391646 | AD14: 5.7267581 | AE14: 8.1166137 | AG14: 4.2550296 | AH14: 5.889631 | AJ14: 5.4781597 | AK14: 7.7913062 | AM14: 4.0687845 | AN14: 5.650619 | AP14: 5.240565 | AQ14: 7.4795567 | AS14: 3.8908348 | AT14: 5.4216729 | AV14: 5.0134802 | AW14: 7.1807835 | AY14: 3.7208065 | AZ14: 5.2023571 | BB14: 4.7964338 | BC14: 6.8944301 | BE14: 3.5583424 | BF14: 4.992255 | BH14: 4.5889758 | BI14: 6.6199648 | BK14: 3.4031017 | BL14: 4.7909686 | BN14: 4.3906764 | BO14: 6.3568788 | BQ14: 3.4031017 | BR14: 4.5981174 | BT14: 4.2011254 | BU14: 6.1046858 | BW14: 0.03106087 | BY14: =C14*$BW14 -> 0.042179258 | BZ14: =D14*$BW14 -> 0.05849341 | CB14: =F14*$BW14 -> 0.043325148 | CC14: =G14*$BW14 -> 0.061627662 | CE14: =I14*$BW14 -> 0.1483906 | CF14: =J14*$BW14 -> 0.20578533 | CH14: =L14*$BW14 -> 0.1907275 | CI14: =M14*$BW14 -> 0.27129947
A15: 9 | B15: Retail trade | C15: 1.1718854 | D15: 1.4600816 | F15: 1.1862664 | G15: 1.4949579 | I15: 6.9593234 | J15: 8.6707966 | L15: 9.2329307 | M15: 11.635534 | O15: 6.5867826 | P15: 8.2496593 | R15: 8.7473501 | S15: 11.090437 | U15: 6.2359791 | V15: 7.8528768 | X15: 8.2902693 | Y15: 10.577289 | AA15: 6.0354372 | AB15: 7.6000019 | AD15: 8.0243279 | AE15: 10.237848 | AG15: 5.8413938 | AH15: 7.3553859 | AJ15: 7.7669764 | AK15: 9.9094472 | AM15: 5.6536362 | AN15: 7.1187548 | AP15: 7.517935 | AQ15: 9.5917225 | AS15: 5.4719588 | AT15: 6.8898438 | AV15: 7.2769331 | AW15: 9.2843216 | AY15: 5.2961628 | AZ15: 6.668397 | BB15: 7.0437088 | BC15: 8.9869042 | BE15: 5.126056 | BF15: 6.4541672 | BH15: 6.8180092 | BI15: 8.6991415 | BK15: 4.9614527 | BL15: 6.2469156 | BN15: 6.5995895 | BO15: 8.4207154 | BQ15: 4.9614527 | BR15: 6.0464114 | BT15: 6.3882129 | BU15: 8.1513188 | BW15: 0.068290261 | BY15: =C15*$BW15 -> 0.08002836 | BZ15: =D15*$BW15 -> 0.099709353 | CB15: =F15*$BW15 -> 0.081010439 | CC15: =G15*$BW15 -> 0.10209107 | CE15: =I15*$BW15 -> 0.47525401 | CF15: =J15*$BW15 -> 0.59213096 | CH15: =L15*$BW15 -> 0.63051925 | CI15: =M15*$BW15 -> 0.79459368
A16: 10 | B16: Finance and insurance | C16: 2.1573166 | D16: 3.0976952 | F16: 1.774004 | G16: 2.3769918 | I16: 4.1567919 | J16: 5.9687459 | L16: 7.4835083 | M16: 10.027169 | O16: 4.0081486 | P16: 5.768653 | R16: 7.2184865 | S16: 9.6991366 | U16: 3.8666812 | V16: 5.5785071 | X16: 6.965581 | Y16: 9.3868715 | AA16: 3.7412829 | AB16: 5.3977033 | AD16: 6.7451285 | AE16: 9.0886043 | AG16: 3.6200772 | AH16: 5.2229559 | AJ16: 6.5318086 | AK16: 8.800064 | AM16: 3.5029189 | AN16: 5.0540548 | AP16: 6.3253844 | AQ16: 8.5209241 | AS16: 3.389668 | AT16: 4.8907972 | AV16: 6.125627 | AW16: 8.2508695 | AY16: 3.2801896 | AZ16: 4.7329878 | BB16: 5.9323154 | BC16: 7.9895959 | BE16: 3.1743536 | BF16: 4.5804383 | BH16: 5.7452361 | BI16: 7.7368098 | BK16: 3.0720346 | BL16: 4.4329672 | BN16: 5.5641831 | BO16: 7.4922275 | BQ16: 3.0720346 | BR16: 4.2903995 | BT16: 5.3889571 | BU16: 7.2555752 | BW16: 0.053476297 | BY16: =C16*$BW16 -> 0.1153653 | BZ16: =D16*$BW16 -> 0.16565327 | CB16: =F16*$BW16 -> 0.094867163 | CC16: =G16*$BW16 -> 0.12711272 | CE16: =I16*$BW16 -> 0.22228984 | CF16: =J16*$BW16 -> 0.31918643 | CH16: =L16*$BW16 -> 0.40019031 | CI16: =M16*$BW16 -> 0.53621587
A17: 11 | B17: Real estate and rentals | C17: 3.4192725 | D17: 5.4542219 | F17: 1.9002329 | G17: 2.5721301 | I17: 1.7610793 | J17: 2.8091698 | L17: 4.1611639 | M17: 5.6324964 | O17: 1.7418041 | P17: 2.7601345 | R17: 4.1622957 | S17: 5.5971809 | U17: 1.724203 | V17: 2.7143763 | X17: 4.1662507 | Y17: 5.5668003 | AA17: 1.666282 | AB17: 2.6244071 | AD17: 4.0314898 | AE17: 5.387029 | AG17: 1.6103534 | AH17: 2.5375082 | AJ17: 3.9011574 | AK17: 5.2131868 | AM17: 1.5563468 | AN17: 2.453572 | AP17: 3.7751054 | AQ17: 5.0450738 | AS17: 1.5041945 | AT17: 2.3724943 | AV17: 3.6531907 | AW17: 4.8824971 | AY17: 1.4538312 | AZ17: 2.2941749 | BB17: 3.5352752 | BC17: 4.7252702 | BE17: 1.405194 | BF17: 2.2185172 | BH17: 3.4212254 | BI17: 4.5732135 | BK17: 1.3582223 | BL17: 2.1454281 | BN17: 3.3109123 | BO17: 4.4261531 | BQ17: 1.3582223 | BR17: 2.0748178 | BT17: 3.2042114 | BU17: 4.2839214 | BW17: 0.15284818 | BY17: =C17*$BW17 -> 0.52262957 | BZ17: =D17*$BW17 -> 0.83366787 | CB17: =F17*$BW17 -> 0.29044714 | CC17: =G17*$BW17 -> 0.3931454 | CE17: =I17*$BW17 -> 0.26917776 | CF17: =J17*$BW17 -> 0.42937648 | CH17: =L17*$BW17 -> 0.63602632 | CI17: =M17*$BW17 -> 0.8609168
A18: 12 | B18: Professional services | C18: 1.6226866 | D18: 2.5344959 | F18: 1.4696597 | G18: 2.1419706 | I18: 4.9817234 | J18: 7.7810205 | L18: 8.5902869 | M18: 12.520002 | O18: 4.7699377 | P18: 7.48975 | R18: 8.2247508 | S18: 12.05712 | U18: 4.5687234 | V18: 7.2133321 | X18: 7.8774243 | Y18: 11.618088 | AA18: 4.4114684 | AB18: 6.9704809 | AD18: 7.6092816 | AE18: 11.22973 | AG18: 4.2597454 | AH18: 6.7360411 | AJ18: 7.350412 | AK18: 10.854652 | AM18: 4.113355 | AN18: 6.5097129 | AP18: 7.1004893 | AQ18: 10.49239 | AS18: 3.9721053 | AT18: 6.2912076 | AV18: 6.859199 | AW18: 10.142497 | AY18: 3.8358114 | AZ18: 6.0802469 | BB18: 6.6262377 | BC18: 9.8045411 | BE18: 3.7042954 | BF18: 5.876563 | BH18: 6.401313 | BI18: 9.4781055 | BK18: 3.5773857 | BL18: 5.6798976 | BN18: 6.184143 | BO18: 9.1627887 | BQ18: 3.5773857 | BR18: 5.4900019 | BT18: 5.9744558 | BU18: 8.8582038 | BW18: 0.053810866 | BY18: =C18*$BW18 -> 0.087318171 | BZ18: =D18*$BW18 -> 0.13638342 | CB18: =F18*$BW18 -> 0.079083664 | CC18: =G18*$BW18 -> 0.1152613 | CE18: =I18*$BW18 -> 0.26807085 | CF18: =J18*$BW18 -> 0.41870345 | CH18: =L18*$BW18 -> 0.46225078 | CI18: =M18*$BW18 -> 0.67371213
... A26: 20 | B26: Government | C26: 1.0121058 | D26: 1.3716789 | F26: 1.0162618 | G26: 1.5210383 | I26: 8.5813298 | J26: 11.630038 | L26: 8.6165669 | M26: 12.89641 | O26: 8.4595676 | P26: 11.421709 | R26: 8.4940217 | S26: 12.667846 | U26: 8.3396101 | V26: 11.219847 | X26: 8.3733224 | Y26: 12.447271 | AA26: 8.0422553 | AB26: 10.82927 | AD26: 8.0748947 | AE26: 12.017916 | AG26: 7.7555086 | AH26: 10.452437 | AJ26: 7.7871105 | AK26: 11.60357 | AM26: 7.4789912 | AN26: 10.088859 | AP26: 7.50959 | AQ26: 11.203701 | AS26: 7.2123381 | AT26: 9.7380672 | AV26: 7.2419669 | AW26: 10.8178 | AY26: 6.9551973 | AZ26: 9.399607 | BB26: 6.9838881 | BC26: 10.445371 | BE26: 6.7072292 | BF26: 9.073041 | BH26: 6.735013 | BI26: 10.085941 | BK26: 6.4681066 | BL26: 8.7579475 | BN26: 6.4950131 | BO26: 9.7390495 | BQ26: 6.4681066 | BR26: 8.4539197 | BT26: 6.2635717 | BU26: 9.4042552 | BW26: 0.12825149 | BY26: =C26*$BW26 -> 0.12980408 | BZ26: =D26*$BW26 -> 0.17591987 | CB26: =F26*$BW26 -> 0.13033709 | CC26: =G26*$BW26 -> 0.19507544 | CE26: =I26*$BW26 -> 1.1005684 | CF26: =J26*$BW26 -> 1.4915698 | CH26: =L26*$BW26 -> 1.1050876 | CI26: =M26*$BW26 -> 1.6539839
B27: State weighted average 1/ | C27: 1.7969655 | D27: 2.5966254 | F27: 1.5802875 | G27: 2.2034878 | I27: 5.7661992 | J27: 7.8368663 | L27: 7.8352604 | M27: 10.742108 | BY27: =SUM(BY7:BY26) -> 1.7969655 | BZ27: =SUM(BZ7:BZ26) -> 2.5966254 | CB27: =SUM(CB7:CB26) -> 1.5802875 | CC27: =SUM(CC7:CC26) -> 2.2034878 | CE27: =SUM(CE7:CE26) -> 5.7661992 | CF27: =SUM(CF7:CF26) -> 7.8368663 | CH27: =SUM(CH7:CH26) -> 7.8352604 | CI27: =SUM(CI7:CI26) -> 10.742108
A28: 1/ Job as weight.

Sheet direct req.
B1: 2022 direct requirements table (condensed version)
B3: Industry | C3: Agriculture | D3: Mining and Construction | E3: Food processing | F3: Manufacturing | G3: Transportation | H3: Information | I3: Utilities | J3: Wholesale trade | K3: Retail trade | L3: Finance and insurance | M3: Real estate and rentals | N3: Professional services | O3: Business services | P3: Educational services | Q3: Health services | R3: Arts, entertainment, and recreation | S3: Accommodation | T3: Eating and drinking places | U3: Other services | V3: Government | W3: PCE (HH sector)
A4: 1 | B4: Agriculture | C4: 0.070901447 | D4: 0.00097944842 | E4: 0.074912354 | F4: 0.00086355659 | G4: 1.1313637e-05 | H4: 1.2812441e-06 | I4: 7.7427866e-06 | J4: 3.8686016e-05 | K4: 1.5931391e-05 | L4: 1.3095471e-07 | M4: 0.0015021179 | N4: 0.00040699133 | O4: 0.00012616717 | P4: 2.623154e-05 | Q4: 0.00049916563 | R4: 0.00014351561 | S4: 1.5119425e-05 | T4: 0.0092984863 | U4: 0.00044776441 | V4: 1.2705774e-05 | W4: 0.0029115427
A5: 2 | B5: Mining and Construction | C5: 0.022671215 | D5: 0.0019352792 | E5: 0.0076226937 | F5: 0.00081972338 | G5: 0.015672643 | H5: 0.0043694425 | I5: 0.044695517 | J5: 0.0027822076 | K5: 0.0040313823 | L5: 0.0053464814 | M5: 0.048196662 | N5: 0.0048399678 | O5: 0.0037110426 | P5: 0.009262416 | Q5: 0.0032916292 | R5: 0.001383198 | S5: 0.040254519 | T5: 0.023885293 | U5: 0.0055317489 | V5: 0.0022868498 | W5: 0.0044977293
A6: 3 | B6: Food processing | C6: 0.0043397306 | D6: 0 | E6: 0.026641916 | F6: 0.0055032751 | G6: 0.00033484322 | H6: 0.00019117049 | I6: 0 | J6: 0.00016682177 | K6: 4.6840597e-05 | L6: 0 | M6: 0 | N6: 0.0001909872 | O6: 5.0298612e-07 | P6: 8.8747253e-06 | Q6: 0.0018792446 | R6: 5.1520666e-05 | S6: 0.0004357394 | T6: 0.034465513 | U6: 0.00021941472 | V6: 7.2144098e-05 | W6: 0.0030234701
A7: 4 | B7: Manufacturing | C7: 0.0074433728 | D7: 0.0016878676 | E7: 0.0087226372 | F7: 0.0046481531 | G7: 0.0109333 | H7: 0.00025090531 | I7: 0.11798353 | J7: 0.00085948138 | K7: 0.0007245335 | L7: 0.00016673815 | M7: 0.00085915521 | N7: 0.00022865062 | O7: 0.00086188323 | P7: 7.8405965e-05 | Q7: 0.00076984328 | R7: 9.1333151e-05 | S7: 0.00084951476 | T7: 0.011631271 | U7: 0.00064633174 | V7: 0.00011756069 | W7: 0.019702073
A8: 5 | B8: Transportation | C8: 0.053527011 | D8: 0.029421805 | E8: 0.016681126 | F8: 0.015654009 | G8: 0.064273763 | H8: 0.02259488 | I8: 0.01250463 | J8: 0.014555886 | K8: 0.0083545722 | L8: 0.021441458 | M8: 0.006705682 | N8: 0.053272898 | O8: 0.016940488 | P8: 0.0066914086 | Q8: 0.0089856419 | R8: 0.0027908434 | S8: 0.023317391 | T8: 0.017748556 | U8: 0.014837547 | V8: 0.0042076022 | W8: 0.017414612
A9: 6 | B9: Information | C9: 0.00097638433 | D9: 0.00354362 | E9: 0.0027344069 | F9: 0.0019005288 | G9: 0.0056309299 | H9: 0.080785566 | I9: 0.0018639651 | J9: 0.013744812 | K9: 0.0065986511 | L9: 0.020740297 | M9: 0.0030671782 | N9: 0.016774352 | O9: 0.0085098909 | P9: 0.0049790841 | Q9: 0.0059308365 | R9: 0.0015574852 | S9: 0.010217276 | T9: 0.0069451905 | U9: 0.0055348689 | V9: 0.00044422614 | W9: 0.038189332
A10: 7 | B10: Utilities | C10: 0.012142945 | D10: 0.011171061 | E10: 0.018347165 | F10: 0.010002321 | G10: 0.0033319796 | H10: 0.0065912011 | I10: 0.069752273 | J10: 0.0063429938 | K10: 0.012705695 | L10: 0.0043531958 | M10: 0.0046335448 | N10: 0.0083723577 | O10: 0.0088929802 | P10: 0.0022536331 | Q10: 0.013316867 | R10: 0.0042429026 | S10: 0.048924303 | T10: 0.028254457 | U10: 0.013372619 | V10: 0.0012026589 | W10: 0.016909343
A11: 8 | B11: Wholesale trade | C11: 0.024352584 | D11: 0.040320043 | E11: 0.034062185 | F11: 0.012909899 | G11: 0.01045298 | H11: 0.0090055585 | I11: 0.006335709 | J11: 0.013888942 | K11: 0.0020116547 | L11: 0.00086303006 | M11: 0.0027293733 | N11: 0.0055099966 | O11: 0.0041492031 | P11: 0.0011786626 | Q11: 0.0069216456 | R11: 0.00071319981 | S11: 0.0099477757 | T11: 0.027650182 | U11: 0.0041648576 | V11: 0.00079716122 | W11: 0.026941076
A12: 9 | B12: Retail trade | C12: 0.0086509642 | D12: 0.057504572 | E12: 0.011689413 | F12: 0.0039206889 | G12: 0.0011950983 | H12: 0.012558541 | I12: 0.0039886655 | J12: 0.0074967403 | K12: 0.0079962371 | L12: 0.0018212521 | M12: 0.009077197 | N12: 0.013059996 | O12: 0.0083832786 | P12: 0.00020763606 | Q12: 0.0038385157 | R12: 0.00020143499 | S12: 0.0032349816 | T12: 0.004039163 | U12: 0.0060047638 | V12: 1.0463135e-05 | W12: 0.056045344
A13: 10 | B13: Finance and insurance | C13: 0.011020113 | D13: 0.014810516 | E13: 0.0029638045 | F13: 0.0042880148 | G13: 0.0074443628 | H13: 0.018194185 | I13: 0.012252333 | J13: 0.010752032 | K13: 0.011213088 | L13: 0.13511495 | M13: 0.039648527 | N13: 0.010109341 | O13: 0.0061643288 | P13: 0.0015810634 | Q13: 0.0049641955 | R13: 0.0010978277 | S13: 0.028305147 | T13: 0.010964664 | U13: 0.0044073875 | V13: 0.00036133024 | W13: 0.036579478
A14: 11 | B14: Real estate and rentals | C14: 0.029457265 | D14: 0.05681358 | E14: 0.025375002 | F14: 0.01024171 | G14: 0.019201434 | H14: 0.05331748 | I14: 0.0085287636 | J14: 0.034479749 | K14: 0.063844588 | L14: 0.036280173 | M14: 0.031801657 | N14: 0.062997373 | O14: 0.032970323 | P14: 0.019993328 | Q14: 0.038572974 | R14: 0.0063606418 | S14: 0.039565204 | T14: 0.043992379 | U14: 0.03141321 | V14: 0.00079409054 | W14: 0.17751231
A15: 12 | B15: Professional services | C15: 0.0039594877 | D15: 0.068903181 | E15: 0.0099363443 | F15: 0.0066785793 | G15: 0.017060977 | H15: 0.034438014 | I15: 0.031853215 | J15: 0.016648234 | K15: 0.0120216 | L15: 0.040929111 | M15: 0.010756576 | N15: 0.070805003 | O15: 0.047146916 | P15: 0.0048859282 | Q15: 0.027069363 | R15: 0.0058926041 | S15: 0.035858507 | T15: 0.032210596 | U15: 0.013916138 | V15: 0.0011623426 | W15: 0.019328489
... A23: 20 | B23: Government | C23: 0.0082482116 | D23: 0.0030415699 | E23: 0.010458057 | F23: 0.0067347255 | G23: 0.068767842 | H23: 0.009562854 | I23: 0.01251746 | J23: 0.0090650414 | K23: 0.019178774 | L23: 0.016499871 | M23: 0.010673682 | N23: 0.0095202024 | O23: 0.01690754 | P23: 0.0018308578 | Q23: 0.014701035 | R23: 0.0054789492 | S23: 0.028256216 | T23: 0.013455056 | U23: 0.0057949705 | V23: 0.001143645 | W23: 0.062612458
B24: Earnings (household sector) | C24: 0.3200158 | D24: 0.32840956 | E24: 0.22877599 | F24: 0.11910878 | G24: 0.26026388 | H24: 0.12679983 | I24: 0.10395696 | J24: 0.27379109 | K24: 0.26052229 | L24: 0.19132461 | M24: 0.11377564 | N24: 0.40191529 | O24: 0.53836112 | P24: 0.34586366 | Q24: 0.35564515 | R24: 0.57850244 | S24: 0.22631371 | T24: 0.34752863 | U24: 0.35287002 | V24: 0.59455949 | W24: 0
B26: Total intermediate input | C26: 0.27825175 | D26: 0.35590143 | E26: 0.42181902 | F26: 0.12402926 | G26: 0.30518346 | H26: 0.34099103 | I26: 0.39643757 | J26: 0.21827346 | K26: 0.20383502 | L26: 0.40672596 | M26: 0.22795468 | N26: 0.37161071 | O26: 0.21697132 | P26: 0.084960478 | Q26: 0.28565599 | R26: 0.051998047 | S26: 0.41360131 | T26: 0.35822178 | U26: 0.15824708 | V26: 0.017556546
B27: Imports | C27: =+'I-O condensed 2022'!C25/'I-O condensed 2022'!C32 -> 0.14647714 | D27: =+'I-O condensed 2022'!D25/'I-O condensed 2022'!D32 -> 0.16658651 | E27: =+'I-O condensed 2022'!E25/'I-O condensed 2022'!E32 -> 0.19551087 | F27: =+'I-O condensed 2022'!F25/'I-O condensed 2022'!F32 -> 0.56539832 | G27: =+'I-O condensed 2022'!G25/'I-O condensed 2022'!G32 -> 0.08892568 | H27: =+'I-O condensed 2022'!H25/'I-O condensed 2022'!H32 -> 0.2177864 | I27: =+'I-O condensed 2022'!I25/'I-O condensed 2022'!I32 -> 0.057991366 | J27: =+'I-O condensed 2022'!J25/'I-O condensed 2022'!J32 -> 0.10396619 | ... V27: =+'I-O condensed 2022'!V25/'I-O condensed 2022'!V32 -> 0.0063290432
B28: Value Added | C28: =+'I-O condensed 2022'!C31/'I-O condensed 2022'!C32 -> 0.57527111 | D28: =+'I-O condensed 2022'!D31/'I-O condensed 2022'!D32 -> 0.47751207 | E28: =+'I-O condensed 2022'!E31/'I-O condensed 2022'!E32 -> 0.38267012 | F28: =+'I-O condensed 2022'!F31/'I-O condensed 2022'!F32 -> 0.31057241 | G28: =+'I-O condensed 2022'!G31/'I-O condensed 2022'!G32 -> 0.60589086 | H28: =+'I-O condensed 2022'!H31/'I-O condensed 2022'!H32 -> 0.44122257 | I28: =+'I-O condensed 2022'!I31/'I-O condensed 2022'!I32 -> 0.54557107 | J28: =+'I-O condensed 2022'!J31/'I-O condensed 2022'!J32 -> 0.67776036 | ... V28: =+'I-O condensed 2022'!V31/'I-O condensed 2022'!V32 -> 0.97611441
B29: Total | C29: 1 | D29: 1 | E29: 1 | F29: 1 | G29: 1 | H29: 1 | I29: 1 | J29: 1 | K29: 1 | L29: 1 | M29: 1 | N29: 1 | O29: 1 | P29: 1 | Q29: 1 | R29: 1 | S29: 1 | T29: 1 | U29: 1 | V29: 1

Sheet ttll req.- type 1
B1: 2022 type 1 total requirements table (condensed version)
